Workbook
Name allowed149726: 'Valid Values'!$T$2:$T$221
Name allowed149756: 'Valid Values'!$AQ$2:$AQ$5
Name allowed149964: 'Valid Values'!$AH$2:$AH$9
Name allowed149965: 'Valid Values'!$AF$2:$AF$9
Name allowed184838: 'Valid Values'!$GI$2:$GI$16
Name allowed185252: 'Valid Values'!$U$2:$U$70
Name allowed185254: 'Valid Values'!$BJ$2:$BJ$70
Name allowed185256: 'Valid Values'!$GT$2:$GT$70
Name allowed185257: 'Valid Values'!$FK$2:$FK$71
Name allowed192864: 'Valid Values'!$AJ$2:$AJ$4
Name allowed192875: 'Valid Values'!$AP$2:$AP$5
Name allowed194726: 'Valid Values'!$ED$2:$ED$4
Name allowed194739: 'Valid Values'!$EM$2:$EM$5
Name allowed19928: 'Valid Values'!$CW$2:$CW$9
Name allowed200855: 'Valid Values'!$CY$2:$CY$11
Name allowed200866: 'Valid Values'!$CX$2:$CX$56
Name allowed200874: 'Valid Values'!$DA$2:$DA$43
Name allowed200875: 'Valid Values'!$DV$2:$DV$12
Name allowed201479: 'Valid Values'!$BF$2:$BF$3
Name allowed202222: 'Valid Values'!$DG$2:$DG$9
Name allowed20251: 'Valid Values'!$DH$2:$DH$22
Name allowed20252: 'Valid Values'!$DY$2:$DY$17
Name allowed20254: 'Valid Values'!$DU$2:$DU$21
Name allowed202653: 'Valid Values'!$HO$2:$HO$6
Name allowed204373: 'Valid Values'!$EI$2:$EI$6
Name allowed214542: 'Valid Values'!$FD$2:$FD$3
Name allowed217965: 'Valid Values'!$CQ$2:$CQ$20
Name allowed220265: 'Valid Values'!$BW$2:$BW$16
Name allowed220267: 'Valid Values'!$BV$2:$BV$9
Name allowed222414: 'Valid Values'!$DI$2:$DI$3
Name allowed222775: 'Valid Values'!$CR$2:$CR$5
Name allowed222778: 'Valid Values'!$CS$2:$CS$61
Name allowed222782: 'Valid Values'!$IG$2:$IG$5
Name allowed222785: 'Valid Values'!$IH$2:$IH$61
Name allowed222789: 'Valid Values'!$GC$2:$GC$5
Name allowed222792: 'Valid Values'!$GD$2:$GD$61
Name allowed222860: 'Valid Values'!$BD$2:$BD$12
Name allowed222861: 'Valid Values'!$BE$2:$BE$7
Name allowed222862: 'Valid Values'!$DE$2:$DE$12
Name allowed222863: 'Valid Values'!$DF$2:$DF$7
Name allowed222864: 'Valid Values'!$GO$2:$GO$7
Name allowed222865: 'Valid Values'!$GP$2:$GP$12
Name allowed222867: 'Valid Values'!$FE$2:$FE$12
Name allowed222868: 'Valid Values'!$FF$2:$FF$7
Name allowed223412: 'Valid Values'!$EA$2:$EA$10
Name allowed223513: 'Valid Values'!$GQ$2:$GQ$3
Name allowed223515: 'Valid Values'!$FG$2:$FG$3
Name allowed224155: 'Valid Values'!$HD$2:$HD$13
Name allowed224158: 'Valid Values'!$HE$2:$HE$9
Name allowed224163: 'Valid Values'!$GL$2:$GL$12
Name allowed224311: 'Valid Values'!$HM$2:$HM$5
Name allowed224759: 'Valid Values'!$CB$2:$CB$4
Name allowed224768: 'Valid Values'!$HJ$2:$HJ$5
Name allowed224770: 'Valid Values'!$FT$2:$FT$4
Name allowed224843: 'Valid Values'!$AK$2:$AK$5
Name allowed224856: 'Valid Values'!$EE$2:$EE$5
Name allowed224980: 'Valid Values'!$CC$2:$CC$4
Name allowed224989: 'Valid Values'!$HK$2:$HK$5
Name allowed224991: 'Valid Values'!$FU$2:$FU$4
Name allowed225064: 'Valid Values'!$AL$2:$AL$5

Sheet Instructions
A1: New Features | D1: For Mandarin translations of product questions, please click here. All answer inputs should still be provided in English. 点击此处查看所有产品相关问题的中文翻译。
A2: Variant Grouping
A3: If you have indicated that you will provide variant grouping data via template settings, additional columns for variant grouping information have been added to the class | C3: Legends
A4: sheet. Enter a common identifier to indicate which part numbers should be grouped together, select attribute(s) to group variants by (or enter custom category if | C4: Cell Fill Colors
A5: desired category is not included in the dropdown), and provide corresponding variant attribute. Groupings that violate Wayfair's Do Not Join rules will be excluded. | C5: Light Red | D5: Missing required data
A6: If Wayfair detects additional variants, products will be grouped further after submission. | C6: Gray | D6: Not required/will be autofilled*
C7: Red | D7: Error/incorrect answer
A8: Class Sheet Instructions | C8: Blue | D8: Autofill suggested by Wayfair (review needed)
A9: Conditional Formatting | C9: Yellow | D9: Warning
A10: Some answers to questions on the spec sheet are dependent on upstream responses, whether they are related to attributes like material type, existence of features | C10: No fill | D10: Validated/no action required
A11: or compliance. Real-time cell coloring per the legend indicates whether an input is required, has an error or has a conditional rule applied. | D11: * For products that have already been submitted, the entire row will be filled gray and cannot be edited further
A12: Error Guidance
A13: Errors are highlighted on the Error Summary Tab which shows a summary of all errors across all sheets with high level details and hyperlinks to the corresponding | C13: Data Priority
A14: cell where the error occurred. Additionally, a new Error Status Column at the beginning of each class sheet will show the status of each row and will display the first error | C14: Required | D14: Data required for product to be live on site
A15: error message in that row, and will update as errors are resolved from left to right. | C15: Recommended | D15: Not required but recommended to improve search and browse
C16: Additional | D16: Optional but enhances listings for customers
A17: All data provided in the class sheet feeds directly to the customer-facing Product Details Page (PDP), optimizes search and enables order fulfillment. Please ensure the | C17: Conditional | D17: Data may be required based on prior responses
A18: data provided is accurate and as detailed as possible.
A19: Notes: | C19: Data Type
A20: • Column headers provide additional information on the data required for each column. | C20: Text | D20: Enter a text-based response
A21: • Completing Recommended and Additional fields further enhances the customer experience and improves the quality of listings for better product discovery. | C21: Single-Select | D21: Select one option from a list of provided options (listed in a dropdown on the cell)
A22: • Marketing Copy should provide a compelling, informative overview of the product, ensuring it effectively highlights key features, benefits, and use cases. | C22: Multi-Select | D22: Enter one or more options from a list of provided options, separated using a semi-colon (;)
A23: Incorporating comprehensive, descriptive language will enable future enhancements for capturing and improving product tagging. | C23: Number* | D23: Enter a decimal numeric response with up to 2 decimal points
A24: ◦ Provide key selling point(s)/feature(s) that differentiate your product and inform customers about your product and encourage purchase. | C24: Whole Number* | D24: Enter an integer (whole number) numeric response
A25: ◦ Either Marketing Copy OR at least 3 Feature Bullets are required. Feature bullets will be displayed on Wayfair PDP in bulleted form. | C25: Yes or No | D25: Enter a Yes, No or Does Not Apply response (listed in a dropdown on the cell)
A26: • The order in which media is input may not be reflected in order of imagery on the product page. | D26: * Does Not Apply is a valid response when applicable
A27: • If all products in a class have the same answer to a question, a default value can be set. An answer entered in the Default Answer row will be applied to all products
A28: in that class automatically. Additional products added to this class in the future will have the same default value applied as well. For any products that have a
A29: different answer than others in the class, enter the answer manually to the applicable row to bypass the default just for that question and product.
A31: Additional Tabs Instructions
A32: Additional Cartons
A33: If a product ships in more than 5 cartons, use the Additional Cartons tab to submit data for cartons 6 and beyond. To add additional cartons, provide the Supplier Part
A34: Number followed by corresponding data for each carton.
A35: Additional Chemicals
A36: If your product contains more than 5 chemicals that need to be reported for Proposition 65, use the Additional Chemicals tab to add additional data.
A37: Additional Media
A38: If a product has more media files than there are columns for in the class sheet, use the Additional Images, Videos or Documents tabs to add additional data.
A39: Notes:
... A45: The Failed Products tab will only show if products in your template failed to upload. These products will need to be added to a new template and uploaded again.

Sheet Error Summary
A1: This Error Summary tab lists all errors and warnings in the spec sheet. Each entry includes a link to the specific cell and detailed information about the issue.
A2: Status | B2: Location | C2: Sheet Name | D2: Supplier Part Number | E2: Product Name | F2: Field | G2: Provided Answer | H2: Error Message
A3: {=_xlfn.LET(_xlpm.class3Data, GetSheetStatusData(Class3Tracker, Class3Errors), _xlpm.class6Data, GetSheetStatusData(Class6Tracker, Class6Errors), _xlpm.class10Data, GetSheetStatusData(Class10Tracker, Class10Errors), _xlpm.class13Data, GetSheetStatusData(Class13Tracker, Class13Errors), _xlpm.class12Data, GetSheetStatusData(Class12Tracker, Class12Errors), _xlpm.shippingAndFulfillment__cartonsData, GetSheetStatusData(shippingAndFulfillment__cartonsTracker, shippingAndFulfillment__cartonsErrors), _xlpm.propSixtyFive__chemicalsData, GetSheetStatusData(propSixtyFive__chemicalsTracker, propSixtyFive__chemicalsErrors), _xlpm.media__imagesData, GetSheetStatusData(media__imagesTracker, media__imagesErrors), _xlpm.media__videosData, GetSheetStatusData(media__videosTracker, media__videosErrors), _xlpm.media__documentsData, GetSheetStatusData(media__documentsTracker, media__documentsErrors), _xlpm.stackedData, _xlfn.VSTACK(_xlpm.class3Data, _xlpm.class6Data, _xlpm.class10Data, _xlpm.class13Data, _xlpm.class12Data, _xlpm.shippingAndFulfillment__cartonsData, _xlpm.propSixtyFive__chemicalsData, _xlpm.media__imagesData, _xlpm.media__videosData, _xlpm.media__documentsData), _xlfn._xlws.FILTER(_xlpm.stackedData, _xlpm.stackedData<>"", ""))} | B3: =IF(AND(C3<>"", J3<>""), HYPERLINK("#'" & C3 & "'!" & J3, J3), "") | C3: {=_xlfn.LET(_xlpm.class3Data, GetSheetNameData(Class3Tracker, Class3Errors, "3 - Carts & Stands"), _xlpm.class6Data, GetSheetNameData(Class6Tracker, Class6Errors, "6 - TV Stands & Enterta"), _xlpm.class10Data, GetSheetNameData(Class10Tracker, Class10Errors, "10 - Office Chairs"), _xlpm.class13Data, GetSheetNameData(Class13Tracker, Class13Errors, "13 - Dressers & Chests"), _xlpm.class12Data, GetSheetNameData(Class12Tracker, Class12Errors, "12 - Beds"), _xlpm.shippingAndFulfillment__cartonsData, GetSheetNameData(shippingAndFulfillment__cartonsTracker, shippingAndFulfillment__cartonsErrors, "Additional Cartons"), _xlpm.propSixtyFive__chemicalsData, GetSheetNameData(propSixtyFive__chemicalsTracker, propSixtyFive__chemicalsErrors, "Additional Chemicals"), _xlpm.media__imagesData, GetSheetNameData(media__imagesTracker, media__imagesErrors, "Additional Images"), _xlpm.media__videosData, GetSheetNameData(media__videosTracker, media__videosErrors, "Additional Videos"), _xlpm.media__documentsData, GetSheetNameData(media__documentsTracker, media__documentsErrors, "Additional Documents"), _xlpm.stackedData, _xlfn.VSTACK(_xlpm.class3Data, _xlpm.class6Data, _xlpm.class10Data, _xlpm.class13Data, _xlpm.class12Data, _xlpm.shippingAndFulfillment__cartonsData, _xlpm.propSixtyFive__chemicalsData, _xlpm.media__imagesData, _xlpm.media__videosData, _xlpm.media__documentsData), _xlfn._xlws.FILTER(_xlpm.stackedData, _xlpm.stackedData<>"", ""))} | D3: {=_xlfn.LET(_xlpm.class3PartNumbers, GetSheetSupplierPartNumbers(Class3Tracker, Class3Errors, '3 - Carts & Stands'!B:B), _xlpm.class6PartNumbers, GetSheetSupplierPartNumbers(Class6Tracker, Class6Errors, '6 - TV Stands & Enterta'!B:B), _xlpm.class10PartNumbers, GetSheetSupplierPartNumbers(Class10Tracker, Class10Errors, '10 - Office Chairs'!B:B), _xlpm.class13PartNumbers, GetSheetSupplierPartNumbers(Class13Tracker, Class13Errors, '13 - Dressers & Chests'!B:B), _xlpm.class12PartNumbers, GetSheetSupplierPartNumbers(Class12Tracker, Class12Errors, '12 - Beds'!B:B), _xlpm.shippingAndFulfillment__cartonsPartNumbers, GetSheetSupplierPartNumbers(shippingAndFulfillment__cartonsTracker, shippingAndFulfillment__cartonsErrors, 'Additional Cartons'!B:B), _xlpm.propSixtyFive__chemicalsPartNumbers, GetSheetSupplierPartNumbers(propSixtyFive__chemicalsTracker, propSixtyFive__chemicalsErrors, 'Additional Chemicals'!B:B), _xlpm.media__imagesPartNumbers, GetSheetSupplierPartNumbers(media__imagesTracker, media__imagesErrors, 'Additional Images'!B:B), _xlpm.media__videosPartNumbers, GetSheetSupplierPartNumbers(media__videosTracker, media__videosErrors, 'Additional Videos'!B:B), _xlpm.media__documentsPartNumbers, GetSheetSupplierPartNumbers(media__documentsTracker, media__documentsErrors, 'Additional Documents'!B:B), _xlpm.stackedPartNumbers, _xlfn.VSTACK(_xlpm.class3PartNumbers, _xlpm.class6PartNumbers, _xlpm.class10PartNumbers, _xlpm.class13PartNumbers, _xlpm.class12PartNumbers, _xlpm.shippingAndFulfillment__cartonsPartNumbers, _xlpm.propSixtyFive__chemicalsPartNumbers, _xlpm.media__imagesPartNumbers, _xlpm.media__videosPartNumbers, _xlpm.media__documentsPartNumbers), _xlfn._xlws.FILTER(_xlpm.stackedPartNumbers, _xlpm.stackedPartNumbers<>"", ""))} | E3: {=_xlfn.LET(_xlpm.class3ProductNames, GetSheetProductNames(Class3Tracker, Class3Errors, '3 - Carts & Stands'!G:G), _xlpm.class6ProductNames, GetSheetProductNames(Class6Tracker, Class6Errors, '6 - TV Stands & Enterta'!G:G), _xlpm.class10ProductNames, GetSheetProductNames(Class10Tracker, Class10Errors, '10 - Office Chairs'!G:G), _xlpm.class13ProductNames, GetSheetProductNames(Class13Tracker, Class13Errors, '13 - Dressers & Chests'!G:G), _xlpm.class12ProductNames, GetSheetProductNames(Class12Tracker, Class12Errors, '12 - Beds'!G:G), _xlpm.shippingAndFulfillment__cartonsProductNames, GetSheetProductNames(shippingAndFulfillment__cartonsTracker, shippingAndFulfillment__cartonsErrors, 'Additional Cartons'!Z:Z), _xlpm.propSixtyFive__chemicalsProductNames, GetSheetProductNames(propSixtyFive__chemicalsTracker, propSixtyFive__chemicalsErrors, 'Additional Chemicals'!Z:Z), _xlpm.media__imagesProductNames, GetSheetProductNames(media__imagesTracker, media__imagesErrors, 'Additional Images'!Z:Z), _xlpm.media__videosProductNames, GetSheetProductNames(media__videosTracker, media__videosErrors, 'Additional Videos'!Z:Z), _xlpm.media__documentsProductNames, GetSheetProductNames(media__documentsTracker, media__documentsErrors, 'Additional Documents'!Z:Z), _xlpm.stackedProductNames, _xlfn.VSTACK(_xlpm.class3ProductNames, _xlpm.class6ProductNames, _xlpm.class10ProductNames, _xlpm.class13ProductNames, _xlpm.class12ProductNames, _xlpm.shippingAndFulfillment__cartonsProductNames, _xlpm.propSixtyFive__chemicalsProductNames, _xlpm.media__imagesProductNames, _xlpm.media__videosProductNames, _xlpm.media__documentsProductNames), _xlfn._xlws.FILTER(_xlpm.stackedProductNames, _xlpm.stackedProductNames<>"EMPTY_ERROR", ""))} | F3: {=_xlfn.LET( _xlpm.class3QuestionDisplayNames, GetErrorQuestionDisplayNames(Class3Headers, Class3Tracker, Class3Errors) , _xlpm.class6QuestionDisplayNames, GetErrorQuestionDisplayNames(Class6Headers, Class6Tracker, Class6Errors) , _xlpm.class10QuestionDisplayNames, GetErrorQuestionDisplayNames(Class10Headers, Class10Tracker, Class10Errors) , _xlpm.class13QuestionDisplayNames, GetErrorQuestionDisplayNames(Class13Headers, Class13Tracker, Class13Errors) , _xlpm.class12QuestionDisplayNames, GetErrorQuestionDisplayNames(Class12Headers, Class12Tracker, Class12Errors) , _xlpm.shippingAndFulfillment__cartonsQuestionDisplayNames, GetErrorQuestionDisplayNames(shippingAndFulfillment__cartonsHeaders, shippingAndFulfillment__cartonsTracker, shippingAndFulfillment__cartonsErrors) , _xlpm.propSixtyFive__chemicalsQuestionDisplayNames, GetErrorQuestionDisplayNames(propSixtyFive__chemicalsHeaders, propSixtyFive__chemicalsTracker, propSixtyFive__chemicalsErrors) , _xlpm.media__imagesQuestionDisplayNames, GetErrorQuestionDisplayNames(media__imagesHeaders, media__imagesTracker, media__imagesErrors) , _xlpm.media__videosQuestionDisplayNames, GetErrorQuestionDisplayNames(media__videosHeaders, media__videosTracker, media__videosErrors) , _xlpm.media__documentsQuestionDisplayNames, GetErrorQuestionDisplayNames(media__documentsHeaders, media__documentsTracker, media__documentsErrors) , _xlpm.stackedQuestionDisplayNames, _xlfn.VSTACK(_xlpm.class3QuestionDisplayNames, _xlpm.class6QuestionDisplayNames, _xlpm.class10QuestionDisplayNames, _xlpm.class13QuestionDisplayNames, _xlpm.class12QuestionDisplayNames, _xlpm.shippingAndFulfillment__cartonsQuestionDisplayNames, _xlpm.propSixtyFive__chemicalsQuestionDisplayNames, _xlpm.media__imagesQuestionDisplayNames, _xlpm.media__videosQuestionDisplayNames, _xlpm.media__documentsQuestionDisplayNames), _xlfn._xlws.FILTER(_xlpm.stackedQuestionDisplayNames, _xlpm.stackedQuestionDisplayNames<>"", ""))} | G3: {=_xlfn.LET( _xlpm.class3ProvidedAnswers, GetFilteredProvidedAnswers(Class3Answers, Class3Errors, Class3Tracker) , _xlpm.class6ProvidedAnswers, GetFilteredProvidedAnswers(Class6Answers, Class6Errors, Class6Tracker) , _xlpm.class10ProvidedAnswers, GetFilteredProvidedAnswers(Class10Answers, Class10Errors, Class10Tracker) , _xlpm.class13ProvidedAnswers, GetFilteredProvidedAnswers(Class13Answers, Class13Errors, Class13Tracker) , _xlpm.class12ProvidedAnswers, GetFilteredProvidedAnswers(Class12Answers, Class12Errors, Class12Tracker) , _xlpm.shippingAndFulfillment__cartonsProvidedAnswers, GetFilteredProvidedAnswers(shippingAndFulfillment__cartonsAnswers, shippingAndFulfillment__cartonsErrors, shippingAndFulfillment__cartonsTracker) , _xlpm.propSixtyFive__chemicalsProvidedAnswers, GetFilteredProvidedAnswers(propSixtyFive__chemicalsAnswers, propSixtyFive__chemicalsErrors, propSixtyFive__chemicalsTracker) , _xlpm.media__imagesProvidedAnswers, GetFilteredProvidedAnswers(media__imagesAnswers, media__imagesErrors, media__imagesTracker) , _xlpm.media__videosProvidedAnswers, GetFilteredProvidedAnswers(media__videosAnswers, media__videosErrors, media__videosTracker) , _xlpm.media__documentsProvidedAnswers, GetFilteredProvidedAnswers(media__documentsAnswers, media__documentsErrors, media__documentsTracker) , _xlpm.stackedProvidedAnswers, _xlfn.VSTACK(_xlpm.class3ProvidedAnswers, _xlpm.class6ProvidedAnswers, _xlpm.class10ProvidedAnswers, _xlpm.class13ProvidedAnswers, _xlpm.class12ProvidedAnswers, _xlpm.shippingAndFulfillment__cartonsProvidedAnswers, _xlpm.propSixtyFive__chemicalsProvidedAnswers, _xlpm.media__imagesProvidedAnswers, _xlpm.media__videosProvidedAnswers, _xlpm.media__documentsProvidedAnswers), _xlfn._xlws.FILTER(_xlpm.stackedProvidedAnswers, _xlpm.stackedProvidedAnswers<>"EMPTY_ERROR", ""))} | H3: {=_xlfn.LET(_xlpm.class3ErrorMessages, _xlfn.FILTER( _xlfn.TOCOL(Class3Errors), _xlfn.TOCOL((Class3Errors <> "") * (Class3Tracker <> "Valid") * (Class3Tracker <> "Disabled")), "" ), _xlpm.class6ErrorMessages, _xlfn.FILTER( _xlfn.TOCOL(Class6Errors), _xlfn.TOCOL((Class6Errors <> "") * (Class6Tracker <> "Valid") * (Class6Tracker <> "Disabled")), "" ), _xlpm.class10ErrorMessages, _xlfn.FILTER( _xlfn.TOCOL(Class10Errors), _xlfn.TOCOL((Class10Errors <> "") * (Class10Tracker <> "Valid") * (Class10Tracker <> "Disabled")), "" ), _xlpm.class13ErrorMessages, _xlfn.FILTER( _xlfn.TOCOL(Class13Errors), _xlfn.TOCOL((Class13Errors <> "") * (Class13Tracker <> "Valid") * (Class13Tracker <> "Disabled")), "" ), _xlpm.class12ErrorMessages, _xlfn.FILTER( _xlfn.TOCOL(Class12Errors), _xlfn.TOCOL((Class12Errors <> "") * (Class12Tracker <> "Valid") * (Class12Tracker <> "Disabled")), "" ), _xlpm.shippingAndFulfillment__cartonsErrorMessages, _xlfn.FILTER( _xlfn.TOCOL(shippingAndFulfillment__cartonsErrors), _xlfn.TOCOL((shippingAndFulfillment__cartonsErrors <> "") * (shippingAndFulfillment__cartonsTracker <> "Valid") * (shippingAndFulfillment__cartonsTracker <> "Disabled")), "" ), _xlpm.propSixtyFive__chemicalsErrorMessages, _xlfn.FILTER( _xlfn.TOCOL(propSixtyFive__chemicalsErrors), _xlfn.TOCOL((propSixtyFive__chemicalsErrors <> "") * (propSixtyFive__chemicalsTracker <> "Valid") * (propSixtyFive__chemicalsTracker <> "Disabled")), "" ), _xlpm.media__imagesErrorMessages, _xlfn.FILTER( _xlfn.TOCOL(media__imagesErrors), _xlfn.TOCOL((media__imagesErrors <> "") * (media__imagesTracker <> "Valid") * (media__imagesTracker <> "Disabled")), "" ), _xlpm.media__videosErrorMessages, _xlfn.FILTER( _xlfn.TOCOL(media__videosErrors), _xlfn.TOCOL((media__videosErrors <> "") * (media__videosTracker <> "Valid") * (media__videosTracker <> "Disabled")), "" ), _xlpm.media__documentsErrorMessages, _xlfn.FILTER( _xlfn.TOCOL(media__documentsErrors), _xlfn.TOCOL((media__documentsErrors <> "") * (media__documentsTracker <> "Valid") * (media__documentsTracker <> "Disabled")), "" ), _xlpm.stackedErrorMessages, _xlfn.VSTACK(_xlpm.class3ErrorMessages, _xlpm.class6ErrorMessages, _xlpm.class10ErrorMessages, _xlpm.class13ErrorMessages, _xlpm.class12ErrorMessages, _xlpm.shippingAndFulfillment__cartonsErrorMessages, _xlpm.propSixtyFive__chemicalsErrorMessages, _xlpm.media__imagesErrorMessages, _xlpm.media__videosErrorMessages, _xlpm.media__documentsErrorMessages), _xlpm.filteredMessages, _xlfn._xlws.FILTER(_xlpm.stackedErrorMessages, _xlpm.stackedErrorMessages<>"", ""), IFERROR(_xlfn.TEXTAFTER(_xlpm.filteredMessages, ":"), _xlpm.filteredMessages))} | J3: {=_xlfn.LET(_xlpm.class3Addresses, GetSheetLocationAddresses(Class3Tracker, Class3Errors), _xlpm.class6Addresses, GetSheetLocationAddresses(Class6Tracker, Class6Errors), _xlpm.class10Addresses, GetSheetLocationAddresses(Class10Tracker, Class10Errors), _xlpm.class13Addresses, GetSheetLocationAddresses(Class13Tracker, Class13Errors), _xlpm.class12Addresses, GetSheetLocationAddresses(Class12Tracker, Class12Errors), _xlpm.shippingAndFulfillment__cartonsAddresses, GetSheetLocationAddresses(shippingAndFulfillment__cartonsTracker, shippingAndFulfillment__cartonsErrors), _xlpm.propSixtyFive__chemicalsAddresses, GetSheetLocationAddresses(propSixtyFive__chemicalsTracker, propSixtyFive__chemicalsErrors), _xlpm.media__imagesAddresses, GetSheetLocationAddresses(media__imagesTracker, media__imagesErrors), _xlpm.media__videosAddresses, GetSheetLocationAddresses(media__videosTracker, media__videosErrors), _xlpm.media__documentsAddresses, GetSheetLocationAddresses(media__documentsTracker, media__documentsErrors), _xlpm.stackedAddresses, _xlfn.VSTACK(_xlpm.class3Addresses, _xlpm.class6Addresses, _xlpm.class10Addresses, _xlpm.class13Addresses, _xlpm.class12Addresses, _xlpm.shippingAndFulfillment__cartonsAddresses, _xlpm.propSixtyFive__chemicalsAddresses, _xlpm.media__imagesAddresses, _xlpm.media__videosAddresses, _xlpm.media__documentsAddresses), _xlfn._xlws.FILTER(_xlpm.stackedAddresses, _xlpm.stackedAddresses<>"", ""))}
B4: =IF(AND(C4<>"", J4<>""), HYPERLINK("#'" & C4 & "'!" & J4, J4), "")
B5: =IF(AND(C5<>"", J5<>""), HYPERLINK("#'" & C5 & "'!" & J5, J5), "")
B6: =IF(AND(C6<>"", J6<>""), HYPERLINK("#'" & C6 & "'!" & J6, J6), "")
B7: =IF(AND(C7<>"", J7<>""), HYPERLINK("#'" & C7 & "'!" & J7, J7), "")
B8: =IF(AND(C8<>"", J8<>""), HYPERLINK("#'" & C8 & "'!" & J8, J8), "")
B9: =IF(AND(C9<>"", J9<>""), HYPERLINK("#'" & C9 & "'!" & J9, J9), "")
B10: =IF(AND(C10<>"", J10<>""), HYPERLINK("#'" & C10 & "'!" & J10, J10), "")
B11: =IF(AND(C11<>"", J11<>""), HYPERLINK("#'" & C11 & "'!" & J11, J11), "")
B12: =IF(AND(C12<>"", J12<>""), HYPERLINK("#'" & C12 & "'!" & J12, J12), "")
B13: =IF(AND(C13<>"", J13<>""), HYPERLINK("#'" & C13 & "'!" & J13, J13), "")
B14: =IF(AND(C14<>"", J14<>""), HYPERLINK("#'" & C14 & "'!" & J14, J14), "")
B15: =IF(AND(C15<>"", J15<>""), HYPERLINK("#'" & C15 & "'!" & J15, J15), "")
... B6002: =IF(AND(C6002<>"", J6002<>""), HYPERLINK("#'" & C6002 & "'!" & J6002, J6002), "")

Sheet WAYFAIR_USE_ONLY
A1: {"brand_catalog_id": 1, "previous_upload_id": null, "template_type": "DEFAULT_QUESTIONS", "supplier_id": 455634, "template_context": "STANDARD", "app_version": "v2", "product_count": 0, "default_answers_included": true, "default_answers_supported": true, "use_legacy_excel_format": false, "include_variant_grouping": true, "download_template_request_id": "60a3a202-b692-44e4-ba02-96f72434bb32", "sheet_metadata": null} | C1: =_xlfn.INFO("release")
C2: =_xlfn.INFO("system")
C3: {=IF(ISERROR(_xlfn.MAP(A8:A8,_xlfn.LAMBDA(_xlpm.class,_xlpm.class<>""))), "Not Available", "Supported")}
A8: Carts & Stands | B8: AV Cart | C8: No | D8: No | E8: No | F8: Yes | G8: Yes | H8: No | I8: Lithium Metal | J8: Cell | K8: 1 | L8: Stand alone | M8: Cells exceeding 5 grams | N8: Cells of between 20w/h and 60w/h | O8: 2.5kg or less | P8: Yes | Q8: Yes | R8: Yes | S8: Free Standing | T8: Yes | U8: Yes | V8: Yes | W8: Yes | X8: Yes | Y8: Yes | Z8: Yes | AA8: Yes | AB8: Yes | AC8: Yes | AD8: Yes | AE8: 1 | AF8: I | AG8: >0 - ≤25ml | AH8: Yes | AI8: No | AJ8: 1A | AK8: Yes | AL8: Yes | AM8: 30 Days | AN8: Yes | AO8: Yes | AQ8: US | AR8: Arabic | AS8: Yes | AT8: A-alpha-C (2-Amino-9H-pyrido[2,3-b]indole) | AU8: United States | AV8: Small Parcel | AW8: 50 | AX8: 0 | AY8: 0 | AZ8: Yes | BA8: Yes | BB8: Primary Variant | BC8: Color | BD8: Entertainment Center | BE8: Yes | BF8: Yes | BG8: No | BH8: Yes | BI8: Yes | BJ8: Yes | BK8: No | BL8: Yes | BM8: Yes | BN8: Yes | BO8: Yes | BP8: No | BQ8: Yes | BR8: No | BS8: No | BT8: No | BU8: Yes | BV8: No | BW8: No | BX8: Dovetail | BY8: Yes | BZ8: Lithium Metal | CA8: Cell | CB8: 1 | CC8: Stand alone | CD8: Cells exceeding 5 grams | CE8: Cells of between 20w/h and 60w/h | CF8: 2.5kg or less | CG8: Yes | CH8: No | CI8: Yes | CJ8: Yes | CK8: Direct Vent | CL8: Yes | CM8: Yes | CN8: Yes | CO8: Yes | CP8: Yes | CQ8: Yes | CR8: Yes | CS8: Yes | CT8: Yes | CU8: Yes | CV8: Yes | CW8: 1 | CX8: I | CY8: >0 - ≤25ml | CZ8: Yes | DA8: No | DB8: No | DC8: 1A | DD8: Yes | DE8: BIFMA Accredited | DF8: 28" | DG8: Yes | DH8: No Assembly Needed | DI8: 30 Days | DJ8: Yes | DK8: Yes | DL8: Full | DM8: Color | DN8: Bankers Chair | DO8: Metal | DP8: Yes | DQ8: Yes | DR8: Yes | DS8: No | DT8: No | DU8: No | DV8: Yes | DW8: No | DX8: Yes | DY8: No | DZ8: No | EA8: No | EB8: Yes | EC8: No | ED8: No | EE8: No | EF8: No | EG8: Yes | EH8: No | EI8: Dovetail | EJ8: Yes | EK8: No | EL8: Lithium Metal | EM8: Cell | EN8: 1 | EO8: Stand alone | EP8: Cells exceeding 5 grams | EQ8: Cells of between 20w/h and 60w/h | ER8: 2.5kg or less | ES8: Yes | ET8: Yes | EU8: Yes | EV8: No | EW8: No | EX8: Yes | EY8: Yes | EZ8: Less than 3,000 | FA8: Yes | FB8: Yes | FC8: Yes | FD8: Yes | FE8: Yes | FF8: Yes | FG8: Yes | FH8: Yes | FI8: Yes | FJ8: Yes | FK8: Yes | FL8: Yes | FM8: Yes | FN8: Yes | FO8: 1 | FP8: I | FQ8: >0 - ≤25ml | FR8: Yes | FS8: No | FT8: Yes | FU8: 1A | FV8: Yes | FW8: Yes | FX8: BIFMA Accredited | FY8: Yes | FZ8: No Assembly Needed | GA8: 30 Days | GB8: Yes | GC8: Yes | GD8: Full | GE8: Frame Color | GF8: Combo Dresser | GG8: Yes | GH8: No | GI8: No | GJ8: Yes | GK8: Yes | GL8: No | GM8: No | GN8: Metal | GO8: No | GP8: Dovetail | GQ8: Yes | GR8: Yes | GS8: Yes | GT8: Yes | GU8: Particle Board / Chipboard | GV8: Yes | GW8: Yes | GX8: Yes | GY8: Yes | GZ8: Yes | HA8: No | HB8: Yes | HC8: Yes | HD8: Yes | HE8: Yes | HF8: Yes | HG8: Yes | HH8: Yes | HI8: Yes | HJ8: Yes | HK8: Yes | HL8: No | HM8: 1A | HN8: Yes | HO8: Yes | HP8: BIFMA Accredited | HQ8: Yes | HR8: No Assembly Needed | HS8: 30 Days | HT8: Yes | HU8: Yes | HV8: Full | HW8: Color | HX8: Twin | HY8: Standard | HZ8: Yes | IA8: Yes | IB8: Bonded Leather | IC8: Yes | ID8: No | IE8: Yes | IF8: Yes | IG8: Yes | IH8: No | II8: Dovetail | IJ8: Yes | IK8: Cell | IL8: Lithium Metal | IM8: 1 | IN8: Stand alone | IO8: Cells exceeding 5 grams | IP8: Cells of between 20w/h and 60w/h | IQ8: 2.5kg or less | IR8: Yes | IS8: Yes | IT8: No | IU8: Yes | IV8: Yes | IW8: Particle Board / Chipboard | IX8: No | IY8: Suede | IZ8: Chenille | JA8: Beveled | JB8: Yes | JC8: Yes | JD8: Yes | JE8: Yes | JF8: Yes | JG8: Yes | JH8: Yes | JI8: Yes | JJ8: Yes | JK8: Yes | JL8: Yes | JM8: Yes | JN8: Yes | JO8: Yes | JP8: Yes | JQ8: Yes | JR8: Yes | JS8: 1 | JT8: I | JU8: >0 - ≤25ml | JV8: Yes | JW8: No | JX8: 1A | JY8: Yes | JZ8: Yes | KA8: No | KB8: Yes | KC8: Yes | KD8: Yes | KE8: Yes | KF8: No Assembly Needed | KG8: 30 Days | KH8: Yes | KI8: Yes | KJ8: Full | KK8: Size
A9: Multimedia Storage | B9: Book Cart | C9: Yes | D9: Yes | E9: Yes | F9: No | G9: No | H9: Yes | I9: Lithium Ion / Lithium Polymer | J9: Battery | K9: 2 | L9: Contained in product | M9: Batteries of 2 grams or less | N9: Cells exceeding 60w/h | O9: 2.5kg to 5kg | P9: No | Q9: No | R9: No | S9: Fixed | T9: No | U9: No | V9: No | W9: No | X9: No | Y9: No | Z9: No | AA9: No | AB9: No | AC9: No | AD9: No | AE9: 2.2 | AF9: III | AG9: >1L - ≤5L | AH9: No | AI9: Yes | AJ9: 3A or 6A | AK9: No | AL9: No | AM9: 60 Days | AN9: No | AO9: No | AQ9: UK | AR9: Bulgarian | AS9: No | AT9: Abiraterone acetate | AU9: Canada | AV9: LTL | AW9: 55 | AX9: 24 | AY9: 24 | AZ9: No | BA9: No | BB9: Non-Primary Variant | BC9: Finish | BD9: TV Stand | BE9: No | BF9: No | BG9: Yes | BH9: No | BI9: No | BJ9: No | BK9: Yes | BL9: No | BM9: No | BN9: No | BO9: No | BP9: Yes | BQ9: No | BR9: Yes | BS9: Yes | BT9: Yes | BU9: No | BV9: Yes | BW9: Yes | BX9: Mortise and Tenon | BY9: No | BZ9: Lithium Ion / Lithium Polymer | CA9: Battery | CB9: 2 | CC9: Contained in product | CD9: Batteries of 2 grams or less | CE9: Cells exceeding 60w/h | CF9: 2.5kg to 5kg | CG9: No | CH9: Yes | CI9: No | CJ9: No | CK9: Natural Vent | CL9: No | CM9: No | CN9: No | CO9: No | CP9: No | CQ9: No | CR9: No | CS9: No | CT9: No | CU9: No | CV9: No | CW9: 2.2 | CX9: III | CY9: >1L - ≤5L | CZ9: No | DA9: Yes | DB9: Yes | DC9: 3A or 6A | DD9: No | DE9: BIFMA Equivalent | DF9: 24" | DG9: No | DH9: Minimal Assembly Needed | DI9: 60 Days | DJ9: No | DK9: No | DL9: Limited | DM9: Material | DN9: Conference Chair | DO9: Aluminum | DP9: No | DQ9: No | DR9: No | DS9: Yes | DT9: Yes | DU9: Yes | DV9: No | DW9: Yes | DX9: No | DY9: Yes | DZ9: Yes | EA9: Yes | EB9: No | EC9: Yes | ED9: Yes | EE9: Yes | EF9: Yes | EG9: No | EH9: Yes | EI9: Mortise and Tenon | EJ9: No | EK9: Yes | EL9: Lithium Ion / Lithium Polymer | EM9: Battery | EN9: 2 | EO9: Contained in product | EP9: Batteries of 2 grams or less | EQ9: Cells exceeding 60w/h | ER9: 2.5kg to 5kg | ES9: No | ET9: No | EU9: No | EV9: Yes | EW9: Yes | EX9: No | EY9: No | EZ9: 3,000-9,000 | FA9: No | FB9: No | FC9: No | FD9: No | FE9: No | FF9: No | FG9: No | FH9: No | FI9: No | FJ9: No | FK9: No | FL9: No | FM9: No | FN9: No | FO9: 2.2 | FP9: III | FQ9: >1L - ≤5L | FR9: No | FS9: Yes | FT9: No | FU9: 3A or 6A | FV9: No | FW9: No | FX9: BIFMA Equivalent | FY9: No | FZ9: Minimal Assembly Needed | GA9: 60 Days | GB9: No | GC9: No | GD9: Limited | GE9: Upholstery Color | GF9: Double Dresser | GG9: No | GH9: Yes | GI9: Yes | GJ9: No | GK9: No | GL9: Yes | GM9: Yes | GN9: Ceramic | GO9: Yes | GP9: Mortise and Tenon | GQ9: No | GR9: No | GS9: No | GT9: No | GU9: MDF | GV9: No | GW9: No | GX9: No | GY9: No | GZ9: No | HA9: Yes | HB9: No | HC9: No | HD9: No | HE9: No | HF9: No | HG9: No | HH9: No | HI9: No | HJ9: No | HK9: No | HL9: Yes | HM9: 3A or 6A | HN9: No | HO9: No | HP9: BIFMA Equivalent | HQ9: No | HR9: Minimal Assembly Needed | HS9: 60 Days | HT9: No | HU9: No | HV9: Limited | HX9: Extra-long Twin | HY9: Canopy | HZ9: No | IA9: No | IB9: PU | IC9: No | ID9: Yes | IE9: No | IF9: No | IG9: No | IH9: Yes | II9: Mortise and Tenon | IJ9: No | IK9: Battery | IL9: Lithium Ion / Lithium Polymer | IM9: 2 | IN9: Contained in product | IO9: Batteries of 2 grams or less | IP9: Cells exceeding 60w/h | IQ9: 2.5kg to 5kg | IR9: No | IS9: No | IT9: Yes | IU9: No | IV9: No | IW9: MDF | IX9: Yes | IY9: Leather Match | IZ9: Velvet | JA9: Arched | JB9: No | JC9: No | JD9: No | JE9: No | JF9: No | JG9: No | JH9: No | JI9: No | JJ9: No | JK9: No | JL9: No | JM9: No | JN9: No | JO9: No | JP9: No | JQ9: No | JR9: No | JS9: 2.2 | JT9: III | JU9: >1L - ≤5L | JV9: No | JW9: Yes | JX9: 3A or 6A | JY9: No | JZ9: No | KA9: Yes | KB9: No | KC9: No | KD9: No | KE9: No | KF9: Minimal Assembly Needed | KG9: 60 Days | KH9: No | KI9: No | KJ9: Limited | KK9: Color
A10: Speaker Stands | B10: CPU Holder | C10: Does Not Apply | D10: Unavailable | G10: Unavailable | I10: Nickel Cadmium | J10: Button Cell | K10: 3 | L10: Packed with product | M10: Batteries of between 2 and 25 grams | N10: Cells of 20w/h or less | O10: More than 10kg | P10: Unavailable | Q10: Unavailable | R10: Does Not Apply | S10: Wall Mounted | T10: Unavailable | U10: Yes, Compliance Verified Program Member | V10: Does Not Apply | W10: Yes, Compliance Verified Program Member | X10: Yes, Compliance Verified Program Member | Y10: Yes, Compliance Verified Program Member | Z10: Does Not Apply | AA10: Yes, Compliance Verified Program Member | AC10: Yes, Compliance Verified Program Member | AD10: Yes, Compliance Verified Program Member | AE10: 2.1 | AF10: No Packing Group | AG10: >0.5L - ≤1L | AI10: Yes, Compliance Verified Program Member | AJ10: Does Not Apply | AK10: Does Not Apply | AM10: 90 Days | AN10: Does Not Apply | AQ10: EU | AR10: Czech (Czech Republic) | AT10: Acetaldehyde | AU10: Afghanistan | AW10: 60 | AX10: 48 | AY10: 48 | BB10: Not Variant | BC10: Assembly | BE10: Unavailable | BH10: Does Not Apply | BJ10: Unavailable | BK10: Unavailable | BL10: Unavailable | BM10: Does Not Apply | BN10: Unavailable | BO10: Unavailable | BP10: Unavailable | BQ10: Unavailable | BV10: Unavailable | BW10: Does Not Apply | BX10: Rabbet Joint | BY10: Unavailable | BZ10: Nickel Cadmium | CA10: Button Cell | CB10: 3 | CC10: Packed with product | CD10: Batteries of between 2 and 25 grams | CE10: Cells of 20w/h or less | CF10: More than 10kg | CG10: Unavailable | CH10: Unavailable | CI10: Does Not Apply | CJ10: Unavailable | CK10: Vent Free | CL10: Unavailable | CM10: Unavailable | CN10: Unavailable | CO10: Does Not Apply | CP10: Does Not Apply | CQ10: Does Not Apply | CR10: Yes, Compliance Verified Program Member | CS10: Does Not Apply | CV10: Yes, Compliance Verified Program Member | CW10: 2.1 | CX10: No Packing Group | CY10: >0.5L - ≤1L | DA10: Yes, Compliance Verified Program Member | DB10: Yes, Compliance Verified Program Member | DC10: Does Not Apply | DD10: Does Not Apply | DE10: Contract Grade Accredited | DF10: 40" | DH10: Full Assembly Needed | DI10: 90 Days | DJ10: Does Not Apply | DL10: Does Not Apply | DM10: Size | DN10: Drafting Chair | DO10: Solid Wood | DQ10: Unavailable | DR10: Unavailable | DS10: Unavailable | DV10: Unavailable | DW10: Unavailable | DX10: Unavailable | DY10: Unavailable | DZ10: Does Not Apply | EA10: Unavailable | EB10: Unavailable | EC10: Unavailable | ED10: Does Not Apply | EE10: Unavailable | EF10: Unavailable | EG10: Unavailable | EH10: Unavailable | EI10: Rabbet Joint | EJ10: Unavailable | EK10: Unavailable | EL10: Nickel Cadmium | EM10: Button Cell | EN10: 3 | EO10: Packed with product | EP10: Batteries of between 2 and 25 grams | EQ10: Cells of 20w/h or less | ER10: More than 10kg | ES10: Unavailable | ET10: Unavailable | EU10: Does Not Apply | EW10: Unavailable | EX10: Unavailable | EY10: Unavailable | EZ10: 9,000-15,000 | FA10: Yes, Compliance Verified Program Member | FB10: Yes, Compliance Verified Program Member | FC10: Yes, Compliance Verified Program Member | FD10: Yes, Compliance Verified Program Member | FE10: Does Not Apply | FF10: Does Not Apply | FH10: Yes, Compliance Verified Program Member | FI10: Yes, Compliance Verified Program Member | FJ10: Yes, Compliance Verified Program Member | FK10: Yes, Compliance Verified Program Member | FM10: Yes, Compliance Verified Program Member | FN10: Does Not Apply | FO10: 2.1 | FP10: No Packing Group | FQ10: >0.5L - ≤1L | FS10: Yes, Compliance Verified Program Member | FT10: Yes, Compliance Verified Program Member | FU10: Does Not Apply | FV10: Yes, Compliance Verified Program Member | FW10: Does Not Apply | FX10: Contract Grade Accredited | FZ10: Full Assembly Needed | GA10: 90 Days | GB10: Does Not Apply | GD10: Does Not Apply | GE10: Upholstery Material | GF10: Gentlemens Chest | GG10: Unavailable | GI10: Unavailable | GJ10: Unavailable | GN10: Plastic | GO10: Unavailable | GP10: Rabbet Joint | GQ10: Unavailable | GR10: Unavailable | GS10: Unavailable | GT10: Unavailable | GU10: Plywood / Laminate Board | GV10: Unavailable | GW10: Unavailable | GX10: Unavailable | GY10: Unavailable | HA10: Does Not Apply | HC10: Does Not Apply | HD10: Does Not Apply | HE10: Does Not Apply | HF10: Does Not Apply | HG10: Yes, Compliance Verified Program Member | HH10: Does Not Apply | HI10: Does Not Apply | HL10: Yes, Compliance Verified Program Member | HM10: Does Not Apply | HN10: Yes, Compliance Verified Program Member | HO10: Does Not Apply | HP10: Contract Grade Accredited | HR10: Full Assembly Needed | HS10: 90 Days | HT10: Does Not Apply | HV10: Unavailable | HX10: Full / Double | HY10: Four Poster | HZ10: Unavailable | IB10: PVC | ID10: Unavailable | IE10: Unavailable | IG10: Unavailable | II10: Rabbet Joint | IJ10: Unavailable | IK10: Button Cell | IL10: Nickel Cadmium | IM10: 3 | IN10: Packed with product | IO10: Batteries of between 2 and 25 grams | IP10: Cells of 20w/h or less | IQ10: More than 10kg | IR10: Unavailable | IS10: Unavailable | IU10: Unavailable | IV10: Unavailable | IW10: Plywood / Laminate Board | IX10: Unavailable | IY10: Top Grain Leather | IZ10: Cord | JA10: Portman | JB10: Unavailable | JC10: Unavailable | JE10: Yes, Compliance Verified Program Member | JF10: Yes, Compliance Verified Program Member | JG10: Yes, Compliance Verified Program Member | JH10: Does Not Apply | JI10: Yes, Compliance Verified Program Member | JJ10: Yes, Compliance Verified Program Member | JK10: Yes, Compliance Verified Program Member | JL10: Yes, Compliance Verified Program Member | JN10: Yes, Compliance Verified Program Member | JO10: Yes, Compliance Verified Program Member | JP10: Does Not Apply | JQ10: Yes, Compliance Verified Program Member | JR10: Yes, Compliance Verified Program Member | JS10: 2.1 | JT10: No Packing Group | JU10: >0.5L - ≤1L | JW10: Yes, Compliance Verified Program Member | JX10: Does Not Apply | JY10: Yes, Compliance Verified Program Member | JZ10: Yes, Compliance Verified Program Member | KA10: Yes, Compliance Verified Program Member | KB10: Yes, Compliance Verified Program Member | KC10: Does Not Apply | KD10: Yes, Compliance Verified Program Member | KF10: Full Assembly Needed | KG10: 90 Days | KH10: Does Not Apply | KJ10: Does Not Apply | KK10: Frame Material
A11: TV Stands & Entertainment Centers | B11: File Cart | I11: Nickel Metal Hydride | J11: Does Not Apply | K11: 6 | L11: Does Not Apply | M11: Cells of 1gram or less | N11: Batteries exceeding 300w/h | O11: 5kg to 10kg | Q11: Does Not Apply | S11: Tilt | W11: Does Not Apply | X11: Does Not Apply | Y11: Does Not Apply | AC11: Does Not Apply | AD11: Does Not Apply | AE11: 7 | AF11: II | AG11: >0 - ≤100g | AI11: Unavailable | AM11: 6 Months | AQ11: CA | AR11: Danish | AT11: Acetamide | AU11: Åland Islands | AW11: 65 | AX11: 72 | AY11: 72 | BX11: Basic Butt | BY11: Does Not Apply | BZ11: Nickel Metal Hydride | CA11: Does Not Apply | CB11: 6 | CC11: Does Not Apply | CD11: Cells of 1gram or less | CE11: Batteries exceeding 300w/h | CF11: 5kg to 10kg | CH11: Does Not Apply | CK11: External | CL11: Does Not Apply | CM11: Does Not Apply | CN11: Does Not Apply | CR11: Does Not Apply | CV11: Does Not Apply | CW11: 7 | CX11: II | CY11: >0 - ≤100g | DA11: Unavailable | DB11: Does Not Apply | DE11: Unavailable | DF11: 32" | DH11: Does Not Apply | DI11: 6 Months | DM11: Fireplace Included | DN11: Executive Chair | DO11: Composite | DV11: Does Not Apply | DX11: Does Not Apply | EH11: Does Not Apply | EI11: Basic Butt | EJ11: Does Not Apply | EK11: Does Not Apply | EL11: Nickel Metal Hydride | EM11: Does Not Apply | EN11: 6 | EO11: Does Not Apply | EP11: Cells of 1gram or less | EQ11: Batteries exceeding 300w/h | ER11: 5kg to 10kg | EW11: Does Not Apply | EX11: Does Not Apply | EY11: Does Not Apply | EZ11: Not Tested | FB11: Does Not Apply | FC11: Does Not Apply | FD11: Does Not Apply | FH11: Unavailable | FI11: Unavailable | FJ11: Does Not Apply | FM11: Does Not Apply | FO11: 7 | FP11: II | FQ11: >0 - ≤100g | FS11: Unavailable | FT11: Does Not Apply | FV11: Does Not Apply | FX11: Unavailable | FZ11: Does Not Apply | GA11: 6 Months | GE11: Leather Type | GF11: Lingerie Chest / Semainier | GI11: Does Not Apply | GN11: Wood | GO11: Does Not Apply | GP11: Basic Butt | GQ11: Does Not Apply | GR11: Does Not Apply | GT11: Does Not Apply | GU11: Unavailable | GW11: Does Not Apply | GX11: Does Not Apply | GY11: Does Not Apply | HG11: Does Not Apply | HN11: Does Not Apply | HP11: Unavailable | HR11: Does Not Apply | HS11: 6 Months | HV11: Does Not Apply | HX11: Queen | HY11: Sleigh | HZ11: Does Not Apply | IB11: Vinyl | II11: Basic Butt | IJ11: Does Not Apply | IK11: Does Not Apply | IL11: Nickel Metal Hydride | IM11: 6 | IN11: Does Not Apply | IO11: Cells of 1gram or less | IP11: Batteries exceeding 300w/h | IQ11: 5kg to 10kg | IW11: Unavailable | IY11: Split Grain Leather | IZ11: Denim | JA11: Rectangular | JB11: Does Not Apply | JC11: Does Not Apply | JE11: Does Not Apply | JF11: Does Not Apply | JG11: Does Not Apply | JI11: Does Not Apply | JJ11: Unavailable | JK11: Unavailable | JN11: Does Not Apply | JO11: Does Not Apply | JQ11: Does Not Apply | JR11: Does Not Apply | JS11: 7 | JT11: II | JU11: >0 - ≤100g | JW11: Does Not Apply | JY11: Does Not Apply | JZ11: Does Not Apply | KA11: Does Not Apply | KD11: Yes, Compliance Verified Program or Baby Safety Alliance (fka JPMA) | KF11: Does Not Apply | KG11: 6 Months | KK11: Print/Pattern
A12: Audio Towers | B12: Laptop Cart | I12: Alkaline | K12: 7 | M12: Cells of between 1 and 5 grams | N12: Batteries of between 100w/h and 300 w/h | O12: Does Not Apply | S12: Articulating | AE12: 5.2 | AF12: Does Not Apply | AG12: >100 - ≤500g | AI12: Does Not Apply | AM12: 1 Year | AR12: German | AT12: Acetazolamide | AU12: Albania | AW12: 70 | AX12: 96 | AY12: 96 | BX12: Biscuit Joint | BZ12: Alkaline | CB12: 7 | CD12: Cells of between 1 and 5 grams | CE12: Batteries of between 100w/h and 300 w/h | CF12: Does Not Apply | CK12: Convertible | CW12: 5.2 | CX12: Does Not Apply | CY12: >100 - ≤500g | DA12: Does Not Apply | DE12: Does Not Apply | DF12: 42" | DI12: 1 Year | DN12: Gaming Chair | DO12: Plastic | EI12: Biscuit Joint | EL12: Alkaline | EN12: 7 | EP12: Cells of between 1 and 5 grams | EQ12: Batteries of between 100w/h and 300 w/h | ER12: Does Not Apply | EZ12: 30,000-50,000 | FH12: Does Not Apply | FI12: Does Not Apply | FO12: 5.2 | FP12: Does Not Apply | FQ12: >100 - ≤500g | FS12: Does Not Apply | FX12: Does Not Apply | GA12: 1 Year | GE12: Casters/Glides | GF12: Mini Chest | GN12: Aluminum | GP12: Biscuit Joint | GU12: Does Not Apply | HP12: Does Not Apply | HS12: 1 Year | HX12: King | HY12: TV Bed | IB12: Shagreen Embossed | II12: Biscuit Joint | IL12: Alkaline | IM12: 7 | IO12: Cells of between 1 and 5 grams | IP12: Batteries of between 100w/h and 300 w/h | IQ12: Does Not Apply | IW12: Does Not Apply | IY12: Nubuck | IZ12: Microfiber / Microsuede | JA12: Camelback | JJ12: Does Not Apply | JK12: Does Not Apply | JS12: 5.2 | JT12: Does Not Apply | JU12: >100 - ≤500g | KD12: Does Not Apply | KG12: 1 Year | KK12: Storage
A13: Office Chairs | B13: Printer Stand | I13: Carbon Zinc | K13: 5 | M13: Batteries exceeding 25 grams | N13: Batteries of 100w/h or less | S13: Tank mount | AE13: 6.1 | AG13: >500g - ≤1kg | AM13: 2 Years | AR13: Greek | AT13: Acetochlor | AU13: Algeria | AW13: 77.5 | AX13: 120 | AY13: 120 | BX13: Tongue and Groove | BZ13: Carbon Zinc | CB13: 5 | CD13: Batteries exceeding 25 grams | CE13: Batteries of 100w/h or less | CK13: Recirculating | CW13: 6.1 | CY13: >500g - ≤1kg | DF13: 49" | DI13: 2 Years | DN13: Side Chair | DO13: Acrylic | EI13: Tongue and Groove | EL13: Carbon Zinc | EN13: 5 | EP13: Batteries exceeding 25 grams | EQ13: Batteries of 100w/h or less | EZ13: 15,000-30,000 | FO13: 6.1 | FQ13: >500g - ≤1kg | GA13: 2 Years | GE13: Arm Type | GF13: Standard Dresser / Chest | GN13: Melamine | GP13: Tongue and Groove | HS13: 2 Years | HX13: California King | HY13: Scalloped | IB13: Bicast Leather | II13: Tongue and Groove | IL13: Carbon Zinc | IM13: 5 | IO13: Batteries exceeding 25 grams | IP13: Batteries of 100w/h or less | IY13: Full Grain Leather | IZ13: Twill | JA13: Scooped | JS13: 6.1 | JU13: >500g - ≤1kg | KG13: 2 Years
A14: Beds | B14: Utility Cart | I14: Lead Acid (Spillable) | K14: 8 | M14: Does Not Apply | N14: Does Not Apply | S14: Recessed | AE14: 3 | AG14: >125ml - ≤500ml | AM14: 3 Years | AR14: English (United Kingdom) | AT14: Acetohydroxamic acid | AU14: American Samoa | AW14: 85 | AX14: 144 | BX14: Pocket Joint | BZ14: Lead Acid (Spillable) | CB14: 8 | CD14: Does Not Apply | CE14: Does Not Apply | CK14: B-Vent | CW14: 3 | CY14: >125ml - ≤500ml | DF14: 55" | DI14: 3 Years | DN14: Task Chair | DO14: Manufactured Wood | EI14: Pocket Joint | EL14: Lead Acid (Spillable) | EN14: 8 | EP14: Does Not Apply | EQ14: Does Not Apply | EZ14: 50,000+ | FO14: 3 | FQ14: >125ml - ≤500ml | GA14: 3 Years | GE14: Customization | GF14: Unavailable | GN14: Silicone | GP14: Pocket Joint | HS14: 3 Years | HX14: Full XL | HY14: Panel Headboard Design | IB14: Faux Cowhide | II14: Pocket Joint | IL14: Lead Acid (Spillable) | IM14: 8 | IO14: Does Not Apply | IP14: Does Not Apply | IY14: Sheepskin | IZ14: Unavailable | JA14: Stepped | JS14: 3 | JU14: >125ml - ≤500ml | KG14: 3 Years
A15: Dressers & Chests | B15: Laptop/Tablet Storage Cart | I15: Lead Acid (Non-Spillable) | K15: 10 | S15: Unavailable | AE15: 4.1 | AG15: >25 - ≤125ml | AM15: 5 Years | AR15: English (United States) | AT15: 2-Acetylaminofluorene | AU15: Andorra | AW15: 92.5 | AX15: 168 | BX15: Cam Bolt | BZ15: Lead Acid (Non-Spillable) | CB15: 10 | CK15: Does Not Apply | CW15: 4.1 | CY15: >25 - ≤125ml | DF15: 50" | DI15: 5 Years | DN15: Criss Cross Chair | DO15: Solid + Manufactured Wood | EI15: Cam Bolt | EL15: Lead Acid (Non-Spillable) | EN15: 10 | EZ15: Unavailable | FO15: 4.1 | FQ15: >25 - ≤125ml | GA15: 5 Years | GE15: Back Height | GN15: Brass | GP15: Cam Bolt | HS15: 5 Years | HX15: Super Single | HY15: Bookcase | IB15: Faux Sheepskin | II15: Cam Bolt | IL15: Lead Acid (Non-Spillable) | IM15: 10 | IY15: Cowhide | IZ15: Does Not Apply | JA15: Other | JS15: 4.1 | JU15: >25 - ≤125ml | KG15: 5 Years
A16: Nightstands | I16: Silver Oxide | K16: 4 | AE16: 4.3 | AG16: >1kg - ≤5kg | AM16: 10 Years | AR16: Spanish | AT16: Acifluorfen sodium | AU16: Angola | AW16: 100 | AX16: 192 | BX16: Dowel Joint | BZ16: Silver Oxide | CB16: 4 | CW16: 4.3 | CY16: >1kg - ≤5kg | DF16: 58" | DI16: 10 Years | DO16: Steel | EI16: Dowel Joint | EL16: Silver Oxide | EN16: 4 | EZ16: Does Not Apply | FO16: 4.3 | FQ16: >1kg - ≤5kg | GA16: 10 Years | GE16: Team Logo | GN16: Fabric | GP16: Dowel Joint | HS16: 10 Years | HX16: RV King | HY16: Spindle | IB16: Faux Shearing | II16: Dowel Joint | IL16: Silver Oxide | IM16: 4 | IY16: Corrected Grain Leather | JA16: Rounded | JS16: 4.3 | JU16: >1kg - ≤5kg | KG16: 10 Years
A17: Armoires & Wardrobes | I17: Does Not Apply | K17: 9 | AE17: 4.2 | AG17: >5L | AM17: 20 Years | AR17: Finnish | AT17: Acrylamide | AU17: Anguilla | AW17: 110 | AX17: 216 | BX17: Half-Lap | BZ17: Does Not Apply | CB17: 9 | CW17: 4.2 | CY17: >5L | DF17: 65" | DI17: 20 Years | DO17: Iron | EI17: Half-Lap | EL17: Does Not Apply | EN17: 9 | FO17: 4.2 | FQ17: >5L | GA17: 20 Years | GE17: Pattern | GN17: Bamboo | GP17: Half-Lap | HS17: 20 Years | HX17: Short Queen | HY17: Murphy | IB17: Unavailable | II17: Half-Lap | IL17: Does Not Apply | IM17: 9 | IY17: Shearling | JA17: Unavailable | JS17: 4.2 | JU17: >5L | KG17: 20 Years
A18: Daybeds & Guest Beds | K18: Unavailable | AE18: 5.1 | AG18: >5kg | AM18: 25 Years | AR18: French (Canada) | AT18: Acrylonitrile | AU18: Antarctica | AW18: 125 | AX18: 240 | BX18: Box | CB18: Unavailable | CW18: 5.1 | CY18: >5kg | DF18: 75" | DI18: 25 Years | DO18: Cane | EI18: Box | EN18: Unavailable | FO18: 5.1 | FQ18: >5kg | GA18: 25 Years | GN18: Bakelite | GP18: Box | HS18: 25 Years | HX18: Antique / Three Quarter | HY18: Wingback | IB18: Does Not Apply | II18: Box | IM18: Unavailable | IY18: Unavailable | JA18: Does Not Apply | JS18: 5.1 | JU18: >5kg | KG18: 25 Years
A19: Headboards | K19: Does Not Apply | AE19: 2.3 | AG19: Does Not Apply | AM19: Lifetime | AR19: Hungarian | AT19: Actinomycin D | AU19: Antigua and Barbuda | AW19: 150 | AX19: 360 | BX19: Lap | CB19: Does Not Apply | CW19: 2.3 | CY19: Does Not Apply | DF19: 70" | DI19: Lifetime | DO19: Raffia | EI19: Lap | EN19: Does Not Apply | FO19: 2.3 | FQ19: Does Not Apply | GA19: Lifetime | GN19: Nylon | GP19: Lap | HS19: Lifetime | HX19: Split California King | HY19: Open-Frame | II19: Lap | IM19: Does Not Apply | IY19: Does Not Apply | JS19: 2.3 | JU19: Does Not Apply | KG19: Lifetime
A20: Bedroom Sets | AE20: 6.2 | AM20: 15 Years | AR20: Indonesian | AT20: AF-2;[2-(2-furyl)-3-(5-nitro-2-furyl)]acrylamide | AU20: Argentina | AW20: 175 | AX20: 480 | BX20: Double Dowelled | CW20: 6.2 | DF20: 48" | DI20: 15 Years | DO20: Nickel | EI20: Double Dowelled | FO20: 6.2 | GA20: 15 Years | GN20: Enameled Cast Iron | GP20: Double Dowelled | HS20: 15 Years | HX20: Short Full | HY20: Slat Headboard Design | II20: Double Dowelled | JS20: 6.2 | KG20: 15 Years
A21: Easels | AE21: 9 | AM21: 4 Years | AR21: Icelandic | AT21: Aflatoxins | AU21: Armenia | AW21: 200 | AX21: 600 | BX21: Bridle | CW21: 9 | DF21: 43" | DI21: 4 Years | DO21: Glass | EI21: Bridle | FO21: 9 | GA21: 4 Years | GN21: Cast Iron | GP21: Bridle | HS21: 4 Years | HX21: Split King | HY21: Daybed | II21: Bridle | JS21: 9 | KG21: 4 Years
A22: Display Cases | AE22: 8 | AM22: 18 Months | AR22: Italian | AT22: Alachlor | AU22: Aruba | AW22: 250 | AX22: 720 | BX22: Halved | CW22: 8 | DF22: 88" | DI22: 18 Months | DO22: Laminate | EI22: Halved | FO22: 8 | GA22: 18 Months | GN22: Gold Plated | GP22: Halved | HS22: 18 Months | HX22: California Queen | HY22: Unavailable | II22: Halved | JS22: 8 | KG22: 18 Months
A23: Lockers | AE23: Does Not Apply | AM23: 6 Years | AR23: Japanese | AT23: Alcoholic beverages, when associated with alcohol abuse | AU23: Australia | AW23: 300 | AX23: 840 | BX23: Corner Block Reinforced | CW23: Does Not Apply | DF23: 60" | DI23: 6 Years | DO23: Wicker | EI23: Corner Block Reinforced | FO23: Does Not Apply | GA23: 6 Years | GN23: Sterling Silver | GP23: Corner Block Reinforced | HS23: 6 Years | HX23: Split Queen | II23: Corner Block Reinforced | JS23: Does Not Apply | KG23: 6 Years
A24: Lecterns & Podiums | AM24: 7 Years | AR24: Korean | AT24: Aldrin | AU24: Austria | AW24: 400 | AX24: 960 | BX24: Miter | DF24: 78" | DI24: 7 Years | DO24: Leather | EI24: Miter | GA24: 7 Years | GN24: Resin | GP24: Miter | HS24: 7 Years | HX24: Split Top King | II24: Miter | KG24: 7 Years
A25: Desks | AM25: 8 Years | AR25: Norwegian (Bokmål) | AT25: All-trans retinoic acid | AU25: Azerbaijan | AW25: 500 | BX25: Unavailable | DF25: 85" | DI25: 8 Years | DO25: Vinyl | EI25: Unavailable | GA25: 8 Years | GN25: Silver Plated | GP25: Unavailable | HS25: 8 Years | HX25: Split Top Queen | II25: Unavailable | KG25: 8 Years
A26: Literature Racks | AM26: 9 Years | AR26: Dutch | AT26: Aloe Vera, non-decolorized whole leaf extract | AU26: Bahamas | BX26: Does Not Apply | DF26: 77" | DI26: 9 Years | DO26: Foam | EI26: Does Not Apply | GA26: 9 Years | GN26: Rubber | GP26: Does Not Apply | HS26: 9 Years | II26: Does Not Apply | KG26: 9 Years
A27: Filing Cabinets | AM27: 12 Years | AR27: Polish | AT27: Alprazolam | AU27: Bahrain | DI27: 12 Years | DO27: Kiln Dried Hardwood | GA27: 12 Years | GN27: Stainless Steel | HS27: 12 Years | KG27: 12 Years
A28: Bookcases | AM28: 11 Years | AR28: Portuguese | AT28: Amantadine hydrochloride | AU28: Bangladesh | DI28: 11 Years | DO28: Stainless Steel | GA28: 11 Years | GN28: Pewter | HS28: 11 Years | KG28: 11 Years
A29: Classroom Chairs | AM29: 13 Years | AR29: Romanian | AT29: Amikacin sulfate | AU29: Barbados | DI29: 13 Years | DO29: Rubber | GA29: 13 Years | GN29: No Handles | HS29: 13 Years | KG29: 13 Years
A30: Wall & Accent Mirrors | AM30: 14 Years | AR30: Russian | AT30: 2-Aminoanthraquinone | AU30: Belarus | DI30: 14 Years | DO30: Plywood | GA30: 14 Years | GN30: Steel | HS30: 14 Years | KG30: 14 Years
A31: Office Stools | AM31: No Commercial Warranty | AR31: Slovak | AT31: p-Aminoazobenzene | AU31: Belgium | DI31: No Commercial Warranty | DO31: Ceramic | GA31: No Commercial Warranty | GN31: Unavailable | HS31: No Commercial Warranty | KG31: No Commercial Warranty
A32: Office Sets | AM32: Does Not Apply | AR32: Swedish | AT32: o-Aminoazotoluene | AU32: Belize | DI32: Does Not Apply | DO32: Brass | GA32: Does Not Apply | GN32: Does Not Apply | HS32: Does Not Apply | KG32: Does Not Apply
A33: Stackable & Nesting Chairs | AR33: Ukrainian | AT33: 4-Aminobiphenyl (4-aminodiphenyl) | AU33: Benin | DO33: Fabric
A34: Futon Mattresses | AR34: Vietnamese | AT34: 1-Amino-2,4-dibromoanthraquinone | AU34: Bermuda | DO34: Concrete
A35: Pot Racks | AR35: Chinese (S) | AT35: 3-Amino-9-ethylcarbazole hydrochloride | AU35: Bhutan | DO35: Particle Board
A36: Plant Stands & Tables | AR36: Chinese (T) | AT36: 2-Aminofluorene | AU36: Bolivia | DO36: Fiberglass
A37: Accent Chairs | AT37: Aminoglutethimide | AU37: Bosnia and Herzegovina | DO37: Resin
A38: Kitchen Islands | AT38: Aminoglycosides | AU38: Botswana | DO38: Faux Leather
A39: Baker's Racks | AT39: 1-Amino-2-methylanthraquinone | AU39: Bouvet Island | DO39: Cardboard
A40: Wine Racks | AT40: 2-Amino-5-(5-nitro-2-furyl)-1,3,4-thiadiazole | AU40: Brazil | DO40: Genuine Marble
A41: Bar Stools | AT41: 4-Amino-2-nitrophenol | AU41: British Indian Ocean Territory | DO41: High-Density Polyethylene (HDPE)
A42: Mantel & Tabletop Clocks | AT42: Aminopterin | AU42: Brunei Darussalam | DO42: Stone
A43: Grandfather Clocks / Floor Clocks | AT43: Amiodarone hydrochloride | AU43: Bulgaria | DO43: Rope
A44: Conference Tables | AT44: Amitraz | AU44: Burkina Faso | DO44: Bamboo / Rattan
...

Sheet 3 - Carts & Stands
B1: core::supplierPartNumber | C1: core::amazonStandardIdentificationNumber | D1: core::manufacturerId | E1: core::manufacturerPartNumber | F1: core::universalProductCode | G1: core::productName | H1: core::collectionName | I1: core::manufacturerProductUrl | J1: variantGrouping::variantType | K1: variantGrouping::groupReferenceId | L1: variantGrouping::variantGrouping | M1: variantGrouping::variantAttributeNameOnSite | N1: variantGrouping::variantGrouping | O1: variantGrouping::variantAttributeNameOnSite | P1: variantGrouping::variantGrouping | Q1: variantGrouping::variantAttributeNameOnSite | R1: price::wholesalePrice | S1: price::minimumAdvertizedPrice | T1: price::manufacturerSuggestedRetailPrice | U1: featureDescription::romanceCopy | V1: featureDescription::genericFeatures | W1: featureDescription::genericFeatures | X1: featureDescription::genericFeatures | Y1: featureDescription::genericFeatures | Z1: featureDescription::genericFeatures | AA1: shippingAndFulfillment::minimumOrderQuantity | AB1: shippingAndFulfillment::forceQuantityMultiplier | AC1: shippingAndFulfillment::displaySetQuantity | AD1: shippingAndFulfillment::productWeight | AE1: shippingAndFulfillment::shipType | AF1: shippingAndFulfillment::freightClass | AG1: shippingAndFulfillment::leadTime | AH1: shippingAndFulfillment::replacementLeadTime | AI1: shippingAndFulfillment::nationalMotorFreightClass | AJ1: shippingAndFulfillment::flatPack | AK1: shippingAndFulfillment::shipPalletized | AL1: shippingAndFulfillment::weight | AM1: shippingAndFulfillment::height | AN1: shippingAndFulfillment::width | AO1: shippingAndFulfillment::depth | AP1: propSixtyFive::warningRequired | AQ1: propSixtyFive::chemicalId | AR1: propSixtyFive::toxicity | AS1: propSixtyFive::countryOfManufacturer | AT1: media::imageValue | AU1: media::imageValue | AV1: media::imageValue | AW1: media::imageValue | AX1: media::imageValue | AY1: media::videoValue | AZ1: media::documentValue | BA1: media::documentType | BB1: media::legalDocumentType | BC1: media::regionType | BD1: media::language | BE1: media::documentValue | BF1: media::documentType | BG1: media::legalDocumentType | BH1: media::regionType | BI1: media::language | BJ1: media::documentValue | BK1: media::documentType | BL1: media::legalDocumentType | BM1: media::regionType | BN1: media::language | BO1: 70212 | BP1: 149726 | BQ1: 149770 | BR1: 185252 | BS1: 149785 | BT1: 182057 | BU1: 164399 | BV1: 149748 | BW1: 149749 | BX1: 149750 | BY1: 149753 | BZ1: 229333 | CA1: 245268 | CB1: 344983 | CC1: 351568 | CD1: 346774 | CE1: 367308 | CF1: 351573 | CG1: 352308 | CH1: 352295 | CI1: 351604 | CJ1: 363032 | CK1: 149782 | CL1: 382561 | CM1: 149965 | CN1: 383797 | CO1: 149784 | CP1: 384383 | CQ1: 149964 | CR1: 419944 | CS1: 149794 | CT1: 149810 | CU1: 192864 | CV1: 149754 | CW1: 201408 | CX1: 224843 | CY1: 225064 | CZ1: 364709 | DA1: 236080 | DB1: 249312 | DC1: 251061 | DD1: 192875 | DE1: 149756 | DF1: 339306 | DG1: 373554 | DH1: 340804 | DI1: 341056 | DJ1: 369616 | DK1: 368261 | DL1: 375301 | DM1: 376200 | DN1: 385918 | DO1: 415201 | DP1: 149771 | DQ1: 70234 | DR1: 70239 | DS1: 70240 | DT1: 70241 | DU1: 229332 | DV1: 334763 | DW1: 254003 | DX1: 255912
B2: Basic Information | J2: Variants | R2: Pricing | U2: Marketing Information | AA2: Fulfillment Information | AL2: Carton Details | AP2: Compliance | AT2: Media | BO2: Attributes
B3: Required | C3: Additional | D3: Required | E3: Required | F3: Recommended | G3: Required | H3: Additional | I3: Additional | J3: Required | K3: Conditional | L3: Recommended | M3: Conditional | N3: Recommended | O3: Conditional | P3: Recommended | Q3: Conditional | R3: Required | S3: Additional | T3: Additional | U3: Conditional | V3: Conditional | W3: Conditional | X3: Conditional | Y3: Conditional | Z3: Conditional | AA3: Required | AB3: Required | AC3: Required | AD3: Required | AE3: Required | AF3: Conditional | AG3: Required | AH3: Required | AI3: Additional | AJ3: Additional | AK3: Additional | AL3: Required | AM3: Required | AN3: Required | AO3: Required | AP3: Required | AQ3: Conditional | AR3: Conditional | AS3: Required | AT3: Required | AU3: Additional | AV3: Additional | AW3: Additional | AX3: Additional | AY3: Additional | AZ3: Conditional | BA3: Conditional | BB3: Conditional | BC3: Conditional | BD3: Conditional | BE3: Conditional | BF3: Conditional | BG3: Conditional | BH3: Conditional | BI3: Conditional | BJ3: Conditional | BK3: Conditional | BL3: Conditional | BM3: Conditional | BN3: Conditional | BO3: Required | BP3: Required | BQ3: Recommended | BR3: Recommended | BS3: Recommended | BT3: Recommended | BU3: Recommended | BV3: Recommended | BW3: Recommended | BX3: Recommended | BY3: Recommended | BZ3: Required | CA3: Additional | CB3: Additional | CC3: Additional | CD3: Additional | CE3: Additional | CF3: Additional | CG3: Additional | CH3: Additional | CI3: Additional | CJ3: Recommended | CK3: Recommended | CL3: Recommended | CM3: Recommended | CN3: Required | CO3: Recommended | CP3: Recommended | CQ3: Recommended | CR3: Recommended | CS3: Recommended | CT3: Recommended | CU3: Required | CV3: Additional | CW3: Required | CX3: Required | CY3: Required | CZ3: Required | DA3: Required | DB3: Required | DC3: Required | DD3: Required | DE3: Required | DF3: Additional | DG3: Additional | DH3: Additional | DI3: Additional | DJ3: Additional | DK3: Required | DL3: Required | DM3: Additional | DN3: Recommended | DO3: Recommended | DP3: Required | DQ3: Required | DR3: Required | DS3: Recommended | DT3: Required | DU3: Required | DV3: Recommended | DW3: Recommended | DX3: Recommended
