Workbook
Name allowed185254: 'Valid Values'!$V$2:$V$70
Name allowed201479: 'Valid Values'!$R$2:$R$3
Name allowed217965: 'Valid Values'!$BC$2:$BC$20
Name allowed220265: 'Valid Values'!$AI$2:$AI$16
Name allowed220267: 'Valid Values'!$AH$2:$AH$9
Name allowed222775: 'Valid Values'!$BD$2:$BD$5
Name allowed222778: 'Valid Values'!$BE$2:$BE$61
Name allowed222860: 'Valid Values'!$P$2:$P$12
Name allowed222861: 'Valid Values'!$Q$2:$Q$7
Name allowed224759: 'Valid Values'!$AN$2:$AN$4
Name allowed224980: 'Valid Values'!$AO$2:$AO$4
Name allowed227966: 'Valid Values'!$S$2:$S$3
Name allowed236083: 'Valid Values'!$AQ$2:$AQ$3
Name allowed244566: 'Valid Values'!$T$2:$T$6
Name allowed251110: 'Valid Values'!$AR$2:$AR$5
Name allowed255305: 'Valid Values'!$BG$2:$BG$4
Name allowed256090: 'Valid Values'!$BH$2:$BH$22
Name allowed292794: 'Valid Values'!$AG$2:$AG$17
Name allowed293480: 'Valid Values'!$U$2:$U$20
Name allowed310560: 'Valid Values'!$AS$2:$AS$5
Name allowed333812: 'Valid Values'!$BF$2:$BF$26
Name allowed340810: 'Valid Values'!$AU$2:$AU$17
Name allowed341070: 'Valid Values'!$AV$2:$AV$6
Name allowed346869: 'Valid Values'!$W$2:$W$11
Name allowed351619: 'Valid Values'!$X$2:$X$5
Name allowed351641: 'Valid Values'!$Z$2:$Z$5
Name allowed351649: 'Valid Values'!$AC$2:$AC$6
Name allowed352342: 'Valid Values'!$AB$2:$AB$8
Name allowed352351: 'Valid Values'!$AA$2:$AA$8
Name allowed364708: 'Valid Values'!$AP$2:$AP$5
Name allowed367149: 'Valid Values'!$Y$2:$Y$13
Name allowed368262: 'Valid Values'!$AX$2:$AX$6
Name allowed368645: 'Valid Values'!$AD$2:$AD$100
Name allowed369614: 'Valid Values'!$AW$2:$AW$13
Name allowed373560: 'Valid Values'!$AT$2:$AT$35
Name allowed375302: 'Valid Values'!$AY$2:$AY$13
Name allowed379875: 'Valid Values'!$AF$2:$AF$55
Name allowed382060: 'Valid Values'!$AZ$2:$AZ$5
Name allowed384286: 'Valid Values'!$AJ$2:$AJ$14
Name allowed385921: 'Valid Values'!$BA$2:$BA$4
Name allowed420139: 'Valid Values'!$AK$2:$AK$18
Name allowed421601: 'Valid Values'!$BB$2:$BB$6
Name allowed5620: 'Valid Values'!$M$2:$M$3
Name allowed5621: 'Valid Values'!$N$2:$N$26
Name allowed5625: 'Valid Values'!$O$2:$O$22
Name allowed5671: 'Valid Values'!$AM$2:$AM$4
Name allowed5910: 'Valid Values'!$AE$2:$AE$31
Name allowed5938: 'Valid Values'!$AL$2:$AL$7
Name allowedcore__manufacturerId: 'Valid Values'!$A$2:$A$1
Name allowedmedia__documentType: 'Valid Values'!$I$2:$I$16
Name allowedmedia__language: 'Valid Values'!$L$2:$L$30
Name allowedmedia__legalDocumentType: 'Valid Values'!$J$2:$J$506
Name allowedmedia__regionType: 'Valid Values'!$K$2:$K$5
Name allowedpropSixtyFive__chemicalId: 'Valid Values'!$F$2:$F$902
Name allowedpropSixtyFive__countryOfManufacturer: 'Valid Values'!$H$2:$H$248
Name allowedpropSixtyFive__toxicity: 'Valid Values'!$G$2:$G$3
Name allowedshippingAndFulfillment__freightClass: 'Valid Values'!$C$2:$C$19
Name allowedshippingAndFulfillment__leadTime: 'Valid Values'!$D$2:$D$18
Name allowedshippingAndFulfillment__replacementLeadTime: 'Valid Values'!$E$2:$E$7
Name allowedshippingAndFulfillment__shipType: 'Valid Values'!$B$2:$B$3

Sheet Instructions
A1: New Features | D1: For Mandarin translations of product questions, please click here. All answer inputs should still be provided in English. 点击此处查看所有产品相关问题的中文翻译。
A2: Conditional Formatting
A3: Some answers to questions on the spec sheet are dependent on upstream responses, whether they are related to attributes like material type, existence of features | C3: Legends
A4: or compliance. Real-time cell coloring per the legend indicates whether an input is required, has an error or has a conditional rule applied. | C4: Cell Fill Colors
A5: Error Guidance | C5: Light Red | D5: Missing required data
A6: Errors are highlighted on the Error Summary Tab which shows a summary of all errors across all sheets with high level details and hyperlinks to the corresponding | C6: Gray | D6: Not required/will be autofilled*
A7: cell where the error occurred. Additionally, a new Error Status Column at the beginning of each class sheet will show the status of each row and will display the first error | C7: Red | D7: Error/incorrect answer
A8: error message in that row, and will update as errors are resolved from left to right. | C8: Blue | D8: Autofill suggested by Wayfair (review needed)
C9: Yellow | D9: Warning
A10: Class Sheet Instructions | C10: No fill | D10: Validated/no action required
D11: * For products that have already been submitted, the entire row will be filled gray and cannot be edited further
A12: All data provided in the class sheet feeds directly to the customer-facing Product Details Page (PDP), optimizes search and enables order fulfillment. Please ensure the
A13: data provided is accurate and as detailed as possible. | C13: Data Priority
A14: Notes: | C14: Required | D14: Data required for product to be live on site
A15: • Column headers provide additional information on the data required for each column. | C15: Recommended | D15: Not required but recommended to improve search and browse
A16: • Completing Recommended and Additional fields further enhances the customer experience and improves the quality of listings for better product discovery. | C16: Additional | D16: Optional but enhances listings for customers
A17: • Marketing Copy should provide a compelling, informative overview of the product, ensuring it effectively highlights key features, benefits, and use cases. | C17: Conditional | D17: Data may be required based on prior responses
A18: Incorporating comprehensive, descriptive language will enable future enhancements for capturing and improving product tagging.
A19: ◦ Provide key selling point(s)/feature(s) that differentiate your product and inform customers about your product and encourage purchase. | C19: Data Type
A20: ◦ Either Marketing Copy OR at least 3 Feature Bullets are required. Feature bullets will be displayed on Wayfair PDP in bulleted form. | C20: Text | D20: Enter a text-based response
A21: • The order in which media is input may not be reflected in order of imagery on the product page. | C21: Single-Select | D21: Select one option from a list of provided options (listed in a dropdown on the cell)
A22: • If all products in a class have the same answer to a question, a default value can be set. An answer entered in the Default Answer row will be applied to all products | C22: Multi-Select | D22: Enter one or more options from a list of provided options, separated using a semi-colon (;)
A23: in that class automatically. Additional products added to this class in the future will have the same default value applied as well. For any products that have a | C23: Number* | D23: Enter a decimal numeric response with up to 2 decimal points
A24: different answer than others in the class, enter the answer manually to the applicable row to bypass the default just for that question and product. | C24: Whole Number* | D24: Enter an integer (whole number) numeric response
C25: Yes or No | D25: Enter a Yes, No or Does Not Apply response (listed in a dropdown on the cell)
A26: Additional Tabs Instructions | D26: * Does Not Apply is a valid response when applicable
A27: Additional Cartons
A28: If a product ships in more than 5 cartons, use the Additional Cartons tab to submit data for cartons 6 and beyond. To add additional cartons, provide the Supplier Part
A29: Number followed by corresponding data for each carton.
A30: Additional Chemicals
A31: If your product contains more than 5 chemicals that need to be reported for Proposition 65, use the Additional Chemicals tab to add additional data.
A32: Additional Media
A33: If a product has more media files than there are columns for in the class sheet, use the Additional Images, Videos or Documents tabs to add additional data.
A34: Notes:
A35: • A maximum of 3 videos can be shown on a product display page in the media tray. Additional videos can be showcased within Waymore content.
A36: Valid Values
A37: The Valid Values tab shows all acceptable answers to single- and multi-select questions. Hyperlinks below each column header will bring you to the corresponding
A38: values list on this tab.
... A40: The Failed Products tab will only show if products in your template failed to upload. These products will need to be added to a new template and uploaded again.

Sheet Error Summary
A1: This Error Summary tab lists all errors and warnings in the spec sheet. Each entry includes a link to the specific cell and detailed information about the issue.
A2: Status | B2: Location | C2: Sheet Name | D2: Supplier Part Number | E2: Product Name | F2: Field | G2: Provided Answer | H2: Error Message
A3: {=_xlfn.LET(_xlpm.class6Data, GetSheetStatusData(Class6Tracker, Class6Errors), _xlpm.shippingAndFulfillment__cartonsData, GetSheetStatusData(shippingAndFulfillment__cartonsTracker, shippingAndFulfillment__cartonsErrors), _xlpm.propSixtyFive__chemicalsData, GetSheetStatusData(propSixtyFive__chemicalsTracker, propSixtyFive__chemicalsErrors), _xlpm.media__imagesData, GetSheetStatusData(media__imagesTracker, media__imagesErrors), _xlpm.media__videosData, GetSheetStatusData(media__videosTracker, media__videosErrors), _xlpm.media__documentsData, GetSheetStatusData(media__documentsTracker, media__documentsErrors), _xlpm.stackedData, _xlfn.VSTACK(_xlpm.class6Data, _xlpm.shippingAndFulfillment__cartonsData, _xlpm.propSixtyFive__chemicalsData, _xlpm.media__imagesData, _xlpm.media__videosData, _xlpm.media__documentsData), _xlfn._xlws.FILTER(_xlpm.stackedData, _xlpm.stackedData<>"", ""))} | B3: =IF(AND(C3<>"", J3<>""), HYPERLINK("#'" & C3 & "'!" & J3, J3), "") | C3: {=_xlfn.LET(_xlpm.class6Data, GetSheetNameData(Class6Tracker, Class6Errors, "6 - TV Stands & Enterta"), _xlpm.shippingAndFulfillment__cartonsData, GetSheetNameData(shippingAndFulfillment__cartonsTracker, shippingAndFulfillment__cartonsErrors, "Additional Cartons"), _xlpm.propSixtyFive__chemicalsData, GetSheetNameData(propSixtyFive__chemicalsTracker, propSixtyFive__chemicalsErrors, "Additional Chemicals"), _xlpm.media__imagesData, GetSheetNameData(media__imagesTracker, media__imagesErrors, "Additional Images"), _xlpm.media__videosData, GetSheetNameData(media__videosTracker, media__videosErrors, "Additional Videos"), _xlpm.media__documentsData, GetSheetNameData(media__documentsTracker, media__documentsErrors, "Additional Documents"), _xlpm.stackedData, _xlfn.VSTACK(_xlpm.class6Data, _xlpm.shippingAndFulfillment__cartonsData, _xlpm.propSixtyFive__chemicalsData, _xlpm.media__imagesData, _xlpm.media__videosData, _xlpm.media__documentsData), _xlfn._xlws.FILTER(_xlpm.stackedData, _xlpm.stackedData<>"", ""))} | D3: {=_xlfn.LET(_xlpm.class6PartNumbers, GetSheetSupplierPartNumbers(Class6Tracker, Class6Errors, '6 - TV Stands & Enterta'!B:B), _xlpm.shippingAndFulfillment__cartonsPartNumbers, GetSheetSupplierPartNumbers(shippingAndFulfillment__cartonsTracker, shippingAndFulfillment__cartonsErrors, 'Additional Cartons'!B:B), _xlpm.propSixtyFive__chemicalsPartNumbers, GetSheetSupplierPartNumbers(propSixtyFive__chemicalsTracker, propSixtyFive__chemicalsErrors, 'Additional Chemicals'!B:B), _xlpm.media__imagesPartNumbers, GetSheetSupplierPartNumbers(media__imagesTracker, media__imagesErrors, 'Additional Images'!B:B), _xlpm.media__videosPartNumbers, GetSheetSupplierPartNumbers(media__videosTracker, media__videosErrors, 'Additional Videos'!B:B), _xlpm.media__documentsPartNumbers, GetSheetSupplierPartNumbers(media__documentsTracker, media__documentsErrors, 'Additional Documents'!B:B), _xlpm.stackedPartNumbers, _xlfn.VSTACK(_xlpm.class6PartNumbers, _xlpm.shippingAndFulfillment__cartonsPartNumbers, _xlpm.propSixtyFive__chemicalsPartNumbers, _xlpm.media__imagesPartNumbers, _xlpm.media__videosPartNumbers, _xlpm.media__documentsPartNumbers), _xlfn._xlws.FILTER(_xlpm.stackedPartNumbers, _xlpm.stackedPartNumbers<>"", ""))} | E3: {=_xlfn.LET(_xlpm.class6ProductNames, GetSheetProductNames(Class6Tracker, Class6Errors, '6 - TV Stands & Enterta'!G:G), _xlpm.shippingAndFulfillment__cartonsProductNames, GetSheetProductNames(shippingAndFulfillment__cartonsTracker, shippingAndFulfillment__cartonsErrors, 'Additional Cartons'!Z:Z), _xlpm.propSixtyFive__chemicalsProductNames, GetSheetProductNames(propSixtyFive__chemicalsTracker, propSixtyFive__chemicalsErrors, 'Additional Chemicals'!Z:Z), _xlpm.media__imagesProductNames, GetSheetProductNames(media__imagesTracker, media__imagesErrors, 'Additional Images'!Z:Z), _xlpm.media__videosProductNames, GetSheetProductNames(media__videosTracker, media__videosErrors, 'Additional Videos'!Z:Z), _xlpm.media__documentsProductNames, GetSheetProductNames(media__documentsTracker, media__documentsErrors, 'Additional Documents'!Z:Z), _xlpm.stackedProductNames, _xlfn.VSTACK(_xlpm.class6ProductNames, _xlpm.shippingAndFulfillment__cartonsProductNames, _xlpm.propSixtyFive__chemicalsProductNames, _xlpm.media__imagesProductNames, _xlpm.media__videosProductNames, _xlpm.media__documentsProductNames), _xlfn._xlws.FILTER(_xlpm.stackedProductNames, _xlpm.stackedProductNames<>"EMPTY_ERROR", ""))} | F3: {=_xlfn.LET( _xlpm.class6QuestionDisplayNames, GetErrorQuestionDisplayNames(Class6Headers, Class6Tracker, Class6Errors) , _xlpm.shippingAndFulfillment__cartonsQuestionDisplayNames, GetErrorQuestionDisplayNames(shippingAndFulfillment__cartonsHeaders, shippingAndFulfillment__cartonsTracker, shippingAndFulfillment__cartonsErrors) , _xlpm.propSixtyFive__chemicalsQuestionDisplayNames, GetErrorQuestionDisplayNames(propSixtyFive__chemicalsHeaders, propSixtyFive__chemicalsTracker, propSixtyFive__chemicalsErrors) , _xlpm.media__imagesQuestionDisplayNames, GetErrorQuestionDisplayNames(media__imagesHeaders, media__imagesTracker, media__imagesErrors) , _xlpm.media__videosQuestionDisplayNames, GetErrorQuestionDisplayNames(media__videosHeaders, media__videosTracker, media__videosErrors) , _xlpm.media__documentsQuestionDisplayNames, GetErrorQuestionDisplayNames(media__documentsHeaders, media__documentsTracker, media__documentsErrors) , _xlpm.stackedQuestionDisplayNames, _xlfn.VSTACK(_xlpm.class6QuestionDisplayNames, _xlpm.shippingAndFulfillment__cartonsQuestionDisplayNames, _xlpm.propSixtyFive__chemicalsQuestionDisplayNames, _xlpm.media__imagesQuestionDisplayNames, _xlpm.media__videosQuestionDisplayNames, _xlpm.media__documentsQuestionDisplayNames), _xlfn._xlws.FILTER(_xlpm.stackedQuestionDisplayNames, _xlpm.stackedQuestionDisplayNames<>"", ""))} | G3: {=_xlfn.LET( _xlpm.class6ProvidedAnswers, GetFilteredProvidedAnswers(Class6Answers, Class6Errors, Class6Tracker) , _xlpm.shippingAndFulfillment__cartonsProvidedAnswers, GetFilteredProvidedAnswers(shippingAndFulfillment__cartonsAnswers, shippingAndFulfillment__cartonsErrors, shippingAndFulfillment__cartonsTracker) , _xlpm.propSixtyFive__chemicalsProvidedAnswers, GetFilteredProvidedAnswers(propSixtyFive__chemicalsAnswers, propSixtyFive__chemicalsErrors, propSixtyFive__chemicalsTracker) , _xlpm.media__imagesProvidedAnswers, GetFilteredProvidedAnswers(media__imagesAnswers, media__imagesErrors, media__imagesTracker) , _xlpm.media__videosProvidedAnswers, GetFilteredProvidedAnswers(media__videosAnswers, media__videosErrors, media__videosTracker) , _xlpm.media__documentsProvidedAnswers, GetFilteredProvidedAnswers(media__documentsAnswers, media__documentsErrors, media__documentsTracker) , _xlpm.stackedProvidedAnswers, _xlfn.VSTACK(_xlpm.class6ProvidedAnswers, _xlpm.shippingAndFulfillment__cartonsProvidedAnswers, _xlpm.propSixtyFive__chemicalsProvidedAnswers, _xlpm.media__imagesProvidedAnswers, _xlpm.media__videosProvidedAnswers, _xlpm.media__documentsProvidedAnswers), _xlfn._xlws.FILTER(_xlpm.stackedProvidedAnswers, _xlpm.stackedProvidedAnswers<>"EMPTY_ERROR", ""))} | H3: {=_xlfn.LET(_xlpm.class6ErrorMessages, _xlfn.FILTER( _xlfn.TOCOL(Class6Errors), _xlfn.TOCOL((Class6Errors <> "") * (Class6Tracker <> "Valid") * (Class6Tracker <> "Disabled")), "" ), _xlpm.shippingAndFulfillment__cartonsErrorMessages, _xlfn.FILTER( _xlfn.TOCOL(shippingAndFulfillment__cartonsErrors), _xlfn.TOCOL((shippingAndFulfillment__cartonsErrors <> "") * (shippingAndFulfillment__cartonsTracker <> "Valid") * (shippingAndFulfillment__cartonsTracker <> "Disabled")), "" ), _xlpm.propSixtyFive__chemicalsErrorMessages, _xlfn.FILTER( _xlfn.TOCOL(propSixtyFive__chemicalsErrors), _xlfn.TOCOL((propSixtyFive__chemicalsErrors <> "") * (propSixtyFive__chemicalsTracker <> "Valid") * (propSixtyFive__chemicalsTracker <> "Disabled")), "" ), _xlpm.media__imagesErrorMessages, _xlfn.FILTER( _xlfn.TOCOL(media__imagesErrors), _xlfn.TOCOL((media__imagesErrors <> "") * (media__imagesTracker <> "Valid") * (media__imagesTracker <> "Disabled")), "" ), _xlpm.media__videosErrorMessages, _xlfn.FILTER( _xlfn.TOCOL(media__videosErrors), _xlfn.TOCOL((media__videosErrors <> "") * (media__videosTracker <> "Valid") * (media__videosTracker <> "Disabled")), "" ), _xlpm.media__documentsErrorMessages, _xlfn.FILTER( _xlfn.TOCOL(media__documentsErrors), _xlfn.TOCOL((media__documentsErrors <> "") * (media__documentsTracker <> "Valid") * (media__documentsTracker <> "Disabled")), "" ), _xlpm.stackedErrorMessages, _xlfn.VSTACK(_xlpm.class6ErrorMessages, _xlpm.shippingAndFulfillment__cartonsErrorMessages, _xlpm.propSixtyFive__chemicalsErrorMessages, _xlpm.media__imagesErrorMessages, _xlpm.media__videosErrorMessages, _xlpm.media__documentsErrorMessages), _xlpm.filteredMessages, _xlfn._xlws.FILTER(_xlpm.stackedErrorMessages, _xlpm.stackedErrorMessages<>"", ""), IFERROR(_xlfn.TEXTAFTER(_xlpm.filteredMessages, ":"), _xlpm.filteredMessages))} | J3: {=_xlfn.LET(_xlpm.class6Addresses, GetSheetLocationAddresses(Class6Tracker, Class6Errors), _xlpm.shippingAndFulfillment__cartonsAddresses, GetSheetLocationAddresses(shippingAndFulfillment__cartonsTracker, shippingAndFulfillment__cartonsErrors), _xlpm.propSixtyFive__chemicalsAddresses, GetSheetLocationAddresses(propSixtyFive__chemicalsTracker, propSixtyFive__chemicalsErrors), _xlpm.media__imagesAddresses, GetSheetLocationAddresses(media__imagesTracker, media__imagesErrors), _xlpm.media__videosAddresses, GetSheetLocationAddresses(media__videosTracker, media__videosErrors), _xlpm.media__documentsAddresses, GetSheetLocationAddresses(media__documentsTracker, media__documentsErrors), _xlpm.stackedAddresses, _xlfn.VSTACK(_xlpm.class6Addresses, _xlpm.shippingAndFulfillment__cartonsAddresses, _xlpm.propSixtyFive__chemicalsAddresses, _xlpm.media__imagesAddresses, _xlpm.media__videosAddresses, _xlpm.media__documentsAddresses), _xlfn._xlws.FILTER(_xlpm.stackedAddresses, _xlpm.stackedAddresses<>"", ""))}
B4: =IF(AND(C4<>"", J4<>""), HYPERLINK("#'" & C4 & "'!" & J4, J4), "")
B5: =IF(AND(C5<>"", J5<>""), HYPERLINK("#'" & C5 & "'!" & J5, J5), "")
B6: =IF(AND(C6<>"", J6<>""), HYPERLINK("#'" & C6 & "'!" & J6, J6), "")
B7: =IF(AND(C7<>"", J7<>""), HYPERLINK("#'" & C7 & "'!" & J7, J7), "")
B8: =IF(AND(C8<>"", J8<>""), HYPERLINK("#'" & C8 & "'!" & J8, J8), "")
B9: =IF(AND(C9<>"", J9<>""), HYPERLINK("#'" & C9 & "'!" & J9, J9), "")
B10: =IF(AND(C10<>"", J10<>""), HYPERLINK("#'" & C10 & "'!" & J10, J10), "")
B11: =IF(AND(C11<>"", J11<>""), HYPERLINK("#'" & C11 & "'!" & J11, J11), "")
B12: =IF(AND(C12<>"", J12<>""), HYPERLINK("#'" & C12 & "'!" & J12, J12), "")
B13: =IF(AND(C13<>"", J13<>""), HYPERLINK("#'" & C13 & "'!" & J13, J13), "")
B14: =IF(AND(C14<>"", J14<>""), HYPERLINK("#'" & C14 & "'!" & J14, J14), "")
B15: =IF(AND(C15<>"", J15<>""), HYPERLINK("#'" & C15 & "'!" & J15, J15), "")
... B6002: =IF(AND(C6002<>"", J6002<>""), HYPERLINK("#'" & C6002 & "'!" & J6002, J6002), "")

Sheet WAYFAIR_USE_ONLY
A1: {"brand_catalog_id": 1, "previous_upload_id": null, "template_type": "DEFAULT_QUESTIONS", "supplier_id": 455634, "template_context": "STANDARD", "app_version": "v2", "product_count": 0, "default_answers_included": true, "default_answers_supported": true, "use_legacy_excel_format": false, "include_variant_grouping": false, "download_template_request_id": "9dccca51-4ea6-414d-981d-669de11ec959", "sheet_metadata": null} | C1: =_xlfn.INFO("release")
C2: =_xlfn.INFO("system")
C3: {=IF(ISERROR(_xlfn.MAP(A8:A8,_xlfn.LAMBDA(_xlpm.class,_xlpm.class<>""))), "Not Available", "Supported")}
A8: Carts & Stands | B8: Entertainment Center | C8: Yes | D8: Yes | E8: No | F8: Yes | G8: Yes | H8: Yes | I8: No | J8: Yes | K8: Yes | L8: Yes | M8: Yes | N8: No | O8: Yes | P8: No | Q8: No | R8: No | S8: Yes | T8: No | U8: No | V8: Dovetail | W8: Yes | X8: Lithium Metal | Y8: Cell | Z8: 1 | AA8: Stand alone | AB8: Cells exceeding 5 grams | AC8: Cells of between 20w/h and 60w/h | AD8: 2.5kg or less | AE8: Yes | AF8: No | AG8: Yes | AH8: Yes | AI8: Direct Vent | AJ8: Yes | AK8: Yes | AL8: Yes | AM8: Yes | AN8: Yes | AO8: Yes | AP8: Yes | AQ8: Yes | AR8: Yes | AS8: Yes | AT8: Yes | AU8: 1 | AV8: I | AW8: >0 - ≤25ml | AX8: Yes | AY8: No | AZ8: No | BA8: 1A | BB8: Yes | BC8: BIFMA Accredited | BD8: 28" | BE8: Yes | BF8: No Assembly Needed | BG8: 30 Days | BH8: Yes | BI8: Yes | BJ8: Full | BL8: US | BM8: Arabic | BN8: No | BO8: A-alpha-C (2-Amino-9H-pyrido[2,3-b]indole) | BP8: United States | BQ8: Small Parcel | BR8: 50 | BS8: 0 | BT8: 0 | BU8: No | BV8: No
A9: Multimedia Storage | B9: TV Stand | C9: No | D9: No | E9: Yes | F9: No | G9: No | H9: No | I9: Yes | J9: No | K9: No | L9: No | M9: No | N9: Yes | O9: No | P9: Yes | Q9: Yes | R9: Yes | S9: No | T9: Yes | U9: Yes | V9: Mortise and Tenon | W9: No | X9: Lithium Ion / Lithium Polymer | Y9: Battery | Z9: 2 | AA9: Contained in product | AB9: Batteries of 2 grams or less | AC9: Cells exceeding 60w/h | AD9: 2.5kg to 5kg | AE9: No | AF9: Yes | AG9: No | AH9: No | AI9: Natural Vent | AJ9: No | AK9: No | AL9: No | AM9: No | AN9: No | AO9: No | AP9: No | AQ9: No | AR9: No | AS9: No | AT9: No | AU9: 2.2 | AV9: III | AW9: >1L - ≤5L | AX9: No | AY9: Yes | AZ9: Yes | BA9: 3A or 6A | BB9: No | BC9: BIFMA Equivalent | BD9: 24" | BE9: No | BF9: Minimal Assembly Needed | BG9: 60 Days | BH9: No | BI9: No | BJ9: Limited | BL9: UK | BM9: Bulgarian | BN9: Yes | BO9: Abiraterone acetate | BP9: Canada | BQ9: LTL | BR9: 55 | BS9: 24 | BT9: 24 | BU9: Yes | BV9: Yes
A10: Speaker Stands | C10: Unavailable | F10: Does Not Apply | H10: Unavailable | I10: Unavailable | J10: Unavailable | K10: Does Not Apply | L10: Unavailable | M10: Unavailable | N10: Unavailable | O10: Unavailable | T10: Unavailable | U10: Does Not Apply | V10: Rabbet Joint | W10: Unavailable | X10: Nickel Cadmium | Y10: Button Cell | Z10: 3 | AA10: Packed with product | AB10: Batteries of between 2 and 25 grams | AC10: Cells of 20w/h or less | AD10: More than 10kg | AE10: Unavailable | AF10: Unavailable | AG10: Does Not Apply | AH10: Unavailable | AI10: Vent Free | AJ10: Unavailable | AK10: Unavailable | AL10: Unavailable | AM10: Does Not Apply | AN10: Does Not Apply | AO10: Does Not Apply | AP10: Yes, Compliance Verified Program Member | AQ10: Does Not Apply | AT10: Yes, Compliance Verified Program Member | AU10: 2.1 | AV10: No Packing Group | AW10: >0.5L - ≤1L | AY10: Yes, Compliance Verified Program Member | AZ10: Yes, Compliance Verified Program Member | BA10: Does Not Apply | BB10: Does Not Apply | BC10: Contract Grade Accredited | BD10: 40" | BF10: Full Assembly Needed | BG10: 90 Days | BH10: Does Not Apply | BJ10: Does Not Apply | BL10: EU | BM10: Czech (Czech Republic) | BO10: Acetaldehyde | BP10: Afghanistan | BR10: 60 | BS10: 48 | BT10: 48
A11: TV Stands & Entertainment Centers | V11: Basic Butt | W11: Does Not Apply | X11: Nickel Metal Hydride | Y11: Does Not Apply | Z11: 6 | AA11: Does Not Apply | AB11: Cells of 1gram or less | AC11: Batteries exceeding 300w/h | AD11: 5kg to 10kg | AF11: Does Not Apply | AI11: External | AJ11: Does Not Apply | AK11: Does Not Apply | AL11: Does Not Apply | AP11: Does Not Apply | AT11: Does Not Apply | AU11: 7 | AV11: II | AW11: >0 - ≤100g | AY11: Unavailable | AZ11: Does Not Apply | BC11: Unavailable | BD11: 32" | BF11: Does Not Apply | BG11: 6 Months | BL11: CA | BM11: Danish | BO11: Acetamide | BP11: Åland Islands | BR11: 65 | BS11: 72 | BT11: 72
A12: Audio Towers | V12: Biscuit Joint | X12: Alkaline | Z12: 7 | AB12: Cells of between 1 and 5 grams | AC12: Batteries of between 100w/h and 300 w/h | AD12: Does Not Apply | AI12: Convertible | AU12: 5.2 | AV12: Does Not Apply | AW12: >100 - ≤500g | AY12: Does Not Apply | BC12: Does Not Apply | BD12: 42" | BG12: 1 Year | BM12: German | BO12: Acetazolamide | BP12: Albania | BR12: 70 | BS12: 96 | BT12: 96
A13: Office Chairs | V13: Tongue and Groove | X13: Carbon Zinc | Z13: 5 | AB13: Batteries exceeding 25 grams | AC13: Batteries of 100w/h or less | AI13: Recirculating | AU13: 6.1 | AW13: >500g - ≤1kg | BD13: 49" | BG13: 2 Years | BM13: Greek | BO13: Acetochlor | BP13: Algeria | BR13: 77.5 | BS13: 120 | BT13: 120
A14: Beds | V14: Pocket Joint | X14: Lead Acid (Spillable) | Z14: 8 | AB14: Does Not Apply | AC14: Does Not Apply | AI14: B-Vent | AU14: 3 | AW14: >125ml - ≤500ml | BD14: 55" | BG14: 3 Years | BM14: English (United Kingdom) | BO14: Acetohydroxamic acid | BP14: American Samoa | BR14: 85 | BS14: 144
A15: Dressers & Chests | V15: Cam Bolt | X15: Lead Acid (Non-Spillable) | Z15: 10 | AI15: Does Not Apply | AU15: 4.1 | AW15: >25 - ≤125ml | BD15: 50" | BG15: 5 Years | BM15: English (United States) | BO15: 2-Acetylaminofluorene | BP15: Andorra | BR15: 92.5 | BS15: 168
A16: Nightstands | V16: Dowel Joint | X16: Silver Oxide | Z16: 4 | AU16: 4.3 | AW16: >1kg - ≤5kg | BD16: 58" | BG16: 10 Years | BM16: Spanish | BO16: Acifluorfen sodium | BP16: Angola | BR16: 100 | BS16: 192
A17: Armoires & Wardrobes | V17: Half-Lap | X17: Does Not Apply | Z17: 9 | AU17: 4.2 | AW17: >5L | BD17: 65" | BG17: 20 Years | BM17: Finnish | BO17: Acrylamide | BP17: Anguilla | BR17: 110 | BS17: 216
A18: Daybeds & Guest Beds | V18: Box | Z18: Unavailable | AU18: 5.1 | AW18: >5kg | BD18: 75" | BG18: 25 Years | BM18: French (Canada) | BO18: Acrylonitrile | BP18: Antarctica | BR18: 125 | BS18: 240
A19: Headboards | V19: Lap | Z19: Does Not Apply | AU19: 2.3 | AW19: Does Not Apply | BD19: 70" | BG19: Lifetime | BM19: Hungarian | BO19: Actinomycin D | BP19: Antigua and Barbuda | BR19: 150 | BS19: 360
A20: Bedroom Sets | V20: Double Dowelled | AU20: 6.2 | BD20: 48" | BG20: 15 Years | BM20: Indonesian | BO20: AF-2;[2-(2-furyl)-3-(5-nitro-2-furyl)]acrylamide | BP20: Argentina | BR20: 175 | BS20: 480
A21: Easels | V21: Bridle | AU21: 9 | BD21: 43" | BG21: 4 Years | BM21: Icelandic | BO21: Aflatoxins | BP21: Armenia | BR21: 200 | BS21: 600
A22: Display Cases | V22: Halved | AU22: 8 | BD22: 88" | BG22: 18 Months | BM22: Italian | BO22: Alachlor | BP22: Aruba | BR22: 250 | BS22: 720
A23: Lockers | V23: Corner Block Reinforced | AU23: Does Not Apply | BD23: 60" | BG23: 6 Years | BM23: Japanese | BO23: Alcoholic beverages, when associated with alcohol abuse | BP23: Australia | BR23: 300 | BS23: 840
A24: Lecterns & Podiums | V24: Miter | BD24: 78" | BG24: 7 Years | BM24: Korean | BO24: Aldrin | BP24: Austria | BR24: 400 | BS24: 960
A25: Desks | V25: Unavailable | BD25: 85" | BG25: 8 Years | BM25: Norwegian (Bokmål) | BO25: All-trans retinoic acid | BP25: Azerbaijan | BR25: 500
A26: Literature Racks | V26: Does Not Apply | BD26: 77" | BG26: 9 Years | BM26: Dutch | BO26: Aloe Vera, non-decolorized whole leaf extract | BP26: Bahamas
A27: Filing Cabinets | BG27: 12 Years | BM27: Polish | BO27: Alprazolam | BP27: Bahrain
A28: Bookcases | BG28: 11 Years | BM28: Portuguese | BO28: Amantadine hydrochloride | BP28: Bangladesh
A29: Classroom Chairs | BG29: 13 Years | BM29: Romanian | BO29: Amikacin sulfate | BP29: Barbados
A30: Wall & Accent Mirrors | BG30: 14 Years | BM30: Russian | BO30: 2-Aminoanthraquinone | BP30: Belarus
A31: Office Stools | BG31: No Commercial Warranty | BM31: Slovak | BO31: p-Aminoazobenzene | BP31: Belgium
A32: Office Sets | BG32: Does Not Apply | BM32: Swedish | BO32: o-Aminoazotoluene | BP32: Belize
A33: Stackable & Nesting Chairs | BM33: Ukrainian | BO33: 4-Aminobiphenyl (4-aminodiphenyl) | BP33: Benin
A34: Futon Mattresses | BM34: Vietnamese | BO34: 1-Amino-2,4-dibromoanthraquinone | BP34: Bermuda
A35: Pot Racks | BM35: Chinese (S) | BO35: 3-Amino-9-ethylcarbazole hydrochloride | BP35: Bhutan
A36: Plant Stands & Tables | BM36: Chinese (T) | BO36: 2-Aminofluorene | BP36: Bolivia
A37: Accent Chairs | BO37: Aminoglutethimide | BP37: Bosnia and Herzegovina
A38: Kitchen Islands | BO38: Aminoglycosides | BP38: Botswana
A39: Baker's Racks | BO39: 1-Amino-2-methylanthraquinone | BP39: Bouvet Island
A40: Wine Racks | BO40: 2-Amino-5-(5-nitro-2-furyl)-1,3,4-thiadiazole | BP40: Brazil
A41: Bar Stools | BO41: 4-Amino-2-nitrophenol | BP41: British Indian Ocean Territory
A42: Mantel & Tabletop Clocks | BO42: Aminopterin | BP42: Brunei Darussalam
A43: Grandfather Clocks / Floor Clocks | BO43: Amiodarone hydrochloride | BP43: Bulgaria
A44: Conference Tables | BO44: Amitraz | BP44: Burkina Faso
...

Sheet 6 - TV Stands & Enterta
B1: core::supplierPartNumber | C1: core::amazonStandardIdentificationNumber | D1: core::manufacturerId | E1: core::manufacturerPartNumber | F1: core::universalProductCode | G1: core::productName | H1: core::collectionName | I1: core::manufacturerProductUrl | J1: price::wholesalePrice | K1: price::minimumAdvertizedPrice | L1: price::manufacturerSuggestedRetailPrice | M1: featureDescription::romanceCopy | N1: featureDescription::genericFeatures | O1: featureDescription::genericFeatures | P1: featureDescription::genericFeatures | Q1: featureDescription::genericFeatures | R1: featureDescription::genericFeatures | S1: shippingAndFulfillment::minimumOrderQuantity | T1: shippingAndFulfillment::forceQuantityMultiplier | U1: shippingAndFulfillment::displaySetQuantity | V1: shippingAndFulfillment::productWeight | W1: shippingAndFulfillment::shipType | X1: shippingAndFulfillment::freightClass | Y1: shippingAndFulfillment::leadTime | Z1: shippingAndFulfillment::replacementLeadTime | AA1: shippingAndFulfillment::nationalMotorFreightClass | AB1: shippingAndFulfillment::flatPack | AC1: shippingAndFulfillment::shipPalletized | AD1: shippingAndFulfillment::weight | AE1: shippingAndFulfillment::height | AF1: shippingAndFulfillment::width | AG1: shippingAndFulfillment::depth | AH1: propSixtyFive::warningRequired | AI1: propSixtyFive::chemicalId | AJ1: propSixtyFive::toxicity | AK1: propSixtyFive::countryOfManufacturer | AL1: media::imageValue | AM1: media::imageValue | AN1: media::imageValue | AO1: media::imageValue | AP1: media::imageValue | AQ1: media::videoValue | AR1: media::documentValue | AS1: media::documentType | AT1: media::legalDocumentType | AU1: media::regionType | AV1: media::language | AW1: media::documentValue | AX1: media::documentType | AY1: media::legalDocumentType | AZ1: media::regionType | BA1: media::language | BB1: media::documentValue | BC1: media::documentType | BD1: media::legalDocumentType | BE1: media::regionType | BF1: media::language | BG1: 5620 | BH1: 252622 | BI1: 5635 | BJ1: 5911 | BK1: 5636 | BL1: 382543 | BM1: 5634 | BN1: 5678 | BO1: 252625 | BP1: 5621 | BQ1: 5625 | BR1: 222860 | BS1: 222861 | BT1: 5624 | BU1: 220722 | BV1: 221251 | BW1: 218007 | BX1: 5648 | BY1: 5649 | BZ1: 5643 | CA1: 5645 | CB1: 189876 | CC1: 201479 | CD1: 5663 | CE1: 242478 | CF1: 227966 | CG1: 244566 | CH1: 293480 | CI1: 293547 | CJ1: 185254 | CK1: 344955 | CL1: 346869 | CM1: 351619 | CN1: 367149 | CO1: 351641 | CP1: 352351 | CQ1: 352342 | CR1: 351649 | CS1: 5949 | CT1: 5950 | CU1: 5654 | CV1: 368645 | CW1: 370848 | CX1: 5910 | CY1: 379875 | CZ1: 292794 | DA1: 220267 | DB1: 220265 | DC1: 384286 | DD1: 393970 | DE1: 400764 | DF1: 420139 | DG1: 5920 | DH1: 5916 | DI1: 5938 | DJ1: 5671 | DK1: 201426 | DL1: 224759 | DM1: 224980 | DN1: 364708 | DO1: 236083 | DP1: 249364 | DQ1: 251110 | DR1: 310560 | DS1: 339330 | DT1: 373560 | DU1: 340810 | DV1: 341070 | DW1: 369614 | DX1: 368262 | DY1: 375302 | DZ1: 376202 | EA1: 382060 | EB1: 385921 | EC1: 415242 | ED1: 421601 | EE1: 5675 | EF1: 5676 | EG1: 252485 | EH1: 252486 | EI1: 252487 | EJ1: 5681 | EK1: 217965 | EL1: 5674 | EM1: 5682 | EN1: 222775 | EO1: 222778 | EP1: 228934 | EQ1: 333812 | ER1: 254186 | ES1: 255305 | ET1: 256090
B2: Basic Information | J2: Pricing | M2: Marketing Information | S2: Fulfillment Information | AD2: Carton Details | AH2: Compliance | AL2: Media | BG2: Attributes
B3: Required | C3: Additional | D3: Required | E3: Required | F3: Recommended | G3: Required | H3: Additional | I3: Additional | J3: Required | K3: Additional | L3: Additional | M3: Conditional | N3: Conditional | O3: Conditional | P3: Conditional | Q3: Conditional | R3: Conditional | S3: Required | T3: Required | U3: Required | V3: Required | W3: Required | X3: Conditional | Y3: Required | Z3: Required | AA3: Additional | AB3: Additional | AC3: Additional | AD3: Required | AE3: Required | AF3: Required | AG3: Required | AH3: Required | AI3: Conditional | AJ3: Conditional | AK3: Required | AL3: Required | AM3: Additional | AN3: Additional | AO3: Additional | AP3: Additional | AQ3: Additional | AR3: Conditional | AS3: Conditional | AT3: Conditional | AU3: Conditional | AV3: Conditional | AW3: Conditional | AX3: Conditional | AY3: Conditional | AZ3: Conditional | BA3: Conditional | BB3: Conditional | BC3: Conditional | BD3: Conditional | BE3: Conditional | BF3: Conditional | BG3: Required | BH3: Recommended | BI3: Required | BJ3: Required | BK3: Required | BL3: Recommended | BM3: Recommended | BN3: Recommended | BO3: Recommended | BP3: Required | BQ3: Required | BR3: Recommended | BS3: Recommended | BT3: Recommended | BU3: Recommended | BV3: Recommended | BW3: Recommended | BX3: Recommended | BY3: Recommended | BZ3: Recommended | CA3: Required | CB3: Required | CC3: Required | CD3: Recommended | CE3: Recommended | CF3: Required | CG3: Additional | CH3: Recommended | CI3: Recommended | CJ3: Recommended | CK3: Required | CL3: Required | CM3: Required | CN3: Required | CO3: Additional | CP3: Additional | CQ3: Additional | CR3: Additional | CS3: Recommended | CT3: Recommended | CU3: Required | CV3: Recommended | CW3: Recommended | CX3: Recommended | CY3: Required | CZ3: Recommended | DA3: Required | DB3: Required | DC3: Recommended | DD3: Recommended | DE3: Recommended | DF3: Required | DG3: Required | DH3: Recommended | DI3: Recommended | DJ3: Required | DK3: Required | DL3: Required | DM3: Required | DN3: Required | DO3: Required | DP3: Required | DQ3: Required | DR3: Recommended | DS3: Recommended | DT3: Recommended | DU3: Recommended | DV3: Recommended | DW3: Recommended | DX3: Required | DY3: Required | DZ3: Required | EA3: Required | EB3: Recommended | EC3: Recommended | ED3: Recommended | EE3: Required | EF3: Required | EG3: Required | EH3: Required | EI3: Required | EJ3: Recommended | EK3: Required | EL3: Required | EM3: Required | EN3: Required | EO3: Recommended | EP3: Required | EQ3: Recommended | ER3: Recommended | ES3: Recommended | ET3: Recommended
A4: Errors | B4: Supplier Part Number | C4: ASIN or Amazon Seller SKU | D4: Brand | E4: Manufacturer Part Number | F4: Universal Product Code | G4: Product Name | H4: Collection Name | I4: Manufacturer Product URL | J4: Base Cost | K4: Minimum Advertised Price | L4: Manufacturer Suggested Retail Price | M4: Marketing Copy | N4: Feature Bullet 1 | O4: Feature Bullet 2 | P4: Feature Bullet 3 | Q4: Feature Bullet 4 | R4: Feature Bullet 5 | S4: Minimum Order Quantity | T4: Force Quantity Multiplier | U4: Display Set Quantity | V4: Product Weight | W4: Ship Type | X4: Freight Class | Y4: Lead Time | Z4: Replacement Lead Time | AA4: National Motor Freight Class | AB4: Flat Pack | AC4: Ship Palletized | AD4: Carton Weight 1 | AE4: Carton Height 1 | AF4: Carton Width 1 | AG4: Carton Depth 1 | AH4: Warning Required | AI4: Chemical 1 | AJ4: Toxicity 1 | AK4: Country Of Manufacturer | AL4: Image File Name or URL 1 | AM4: Image File Name or URL 2 | AN4: Image File Name or URL 3 | AO4: Image File Name or URL 4 | AP4: Image File Name or URL 5 | AQ4: Video File Name or URL 1 | AR4: Document File Name or URL 1 | AS4: Document Type 1 | AT4: Legal Document Type 1 | AU4: Document Region 1 | AV4: Document Language 1 | AW4: Document File Name or URL 2 | AX4: Document Type 2 | AY4: Legal Document Type 2 | AZ4: Document Region 2 | BA4: Document Language 2 | BB4: Document File Name or URL 3 | BC4: Document Type 3 | BD4: Legal Document Type 3 | BE4: Document Region 3 | BF4: Document Language 3 | BG4: Product Type | BH4: Pier / Bookcase Included | BI4: Drawers Included | BJ4: Number of Drawers | BK4: Cabinets Included | BL4: Shelves Included | BM4: Exterior Shelves Included | BN4: Interior Shelves Included | BO4: Bridge Included | BP4: Furniture Design | BQ4: Material | BR4: Purposeful Distressing Type | BS4: Natural Variation Type | BT4: Gloss Finish | BU4: Mirrored | BV4: Sound Bar Shelf Included | BW4: Adjustable Shelves | BX4: Media Storage Included | BY4: Cable Management | BZ4: Wheels / Casters Included | CA4: Fireplace Included | CB4: Plug-In | CC4: Tipover Restraint Device Included | CD4: Integrated TV Mount Included | CE4: Adjustable Height | CF4: Supplier Intended and Approved Use | CG4: Country of Origin - Additional Details | CH4: Main Wood Joinery Method | CI4: Kiln-Dried Wood | CJ4: Wood Species | CK4: Battery or Batteries Included | CL4: Battery Composition | CM4: Battery Type | CN4: Number of Batteries | CO4: Battery Shipment | CP4: Lithium Content | CQ4: Watt Rating of Cells / Battery | CR4: Weight of Cells / Battery | CS4: Adjustable Temperature | CT4: Adjustable Flame | CU4: Weight Capacity | CV4: Product Care | CW4: Unfinished | CX4: Shelf Material | CY4: Color / Finish | CZ4: Drawer Glide Type & Extension | DA4: Vent Type | DB4: Fuel Type | DC4: Door Design | DD4: Ribbed Detailing | DE4: Fluted Detailing | DF4: Pieces Included | DG4: Number of Cabinets | DH4: Drawer Safety Stop | DI4: Fireplace Type | DJ4: General Certificate of Conformity (GCC) | DK4: Composite Wood Product (CWP) | DL4: CARB Phase II Compliant (formaldehyde emissions) | DM4: TSCA Title VI Compliant (formaldehyde emissions) | DN4: CANFER Compliant | DO4: Uniform Packaging and Labeling Regulations (UPLR) Compliant | DP4: Canada Product Restriction | DQ4: Reason for Restriction | DR4: UL 1678 Listed | DS4: Hazardous Material / Dangerous Goods | DT4: UN or ID number | DU4: Hazard Class(es) | DV4: Packing Group | DW4: Hazardous Material Weight | DX4: Energy Efficiency Regulations Compliant | DY4: Safety Listing(s) | DZ4: Safety Listing(s) Registration Number | EA4: CPSC - 16 CFR 1263 Compliant (Reese's Law) | EB4: ISTA Certified | EC4: Sustainability & Social Responsibility Certifications (North America Only) | ED4: Commercial Certifications | EE4: TV Stand Width - Side to Side | EF4: TV Stand Depth - Front to Back | EG4: Overall Entertainment Center Height - Top to Bottom | EH4: Overall Entertainment Center Width - Side to Side | EI4: Overall Entertainment Center Depth - Front to Back | EJ4: Overall Product Weight | EK4: Maximum TV Screen Size Accommodated | EL4: TV Stand Overall Height - Top to Bottom | EM4: Assembly Required | EN4: Level of Assembly | EO4: Additional Tools Required (Not Included) | EP4: Commercial Warranty | EQ4: Commercial Warranty Length | ER4: Product Warranty | ES4: Full or Limited Warranty | ET4: Warranty Length
